Workbook

Sheet 요약
A1: 다녀가 용! 재화 배치 임시값 요약
A2: 기준: 20261001_레벨디자인_Ver03_백승오 (스테이지·건물) + 20260930_컨셉기획서_Ver01_오승명 p10 (재화). 모든 골드 값은 임시값이며 설정 시트에서 조절.
A4: 시대 | B4: 스테이지 골드 | C4: 보너스 골드 | D4: 시대 합계 | E4: 전체 대비 비중 | F4: 1-1 대비 배수 (스테이지 1개 평균)
A5: 원시 | B5: =SUMIF('스테이지별 골드'!$A$5:$A$32,A5,'스테이지별 골드'!$M$5:$M$32) -> 1044 | C5: =SUMIF('스테이지별 골드'!$A$5:$A$32,A5,'스테이지별 골드'!$Q$5:$Q$32) -> 2704 | D5: =B5+C5 -> 3748 | E5: =IF($D$12=0,0,D5/$D$12) -> 0.0017780789 | F5: =IF('스테이지별 골드'!$M$5=0,0,B5/4/'스테이지별 골드'!$M$5) -> 2.4622642
A6: 고대 | B6: =SUMIF('스테이지별 골드'!$A$5:$A$32,A6,'스테이지별 골드'!$M$5:$M$32) -> 3339 | C6: =SUMIF('스테이지별 골드'!$A$5:$A$32,A6,'스테이지별 골드'!$Q$5:$Q$32) -> 7448 | D6: =B6+C6 -> 10787 | E6: =IF($D$12=0,0,D6/$D$12) -> 0.0051174324 | F6: =IF('스테이지별 골드'!$M$5=0,0,B6/4/'스테이지별 골드'!$M$5) -> 7.875
A7: 중세 | B7: =SUMIF('스테이지별 골드'!$A$5:$A$32,A7,'스테이지별 골드'!$M$5:$M$32) -> 9740 | C7: =SUMIF('스테이지별 골드'!$A$5:$A$32,A7,'스테이지별 골드'!$Q$5:$Q$32) -> 19654 | D7: =B7+C7 -> 29394 | E7: =IF($D$12=0,0,D7/$D$12) -> 0.013944731 | F7: =IF('스테이지별 골드'!$M$5=0,0,B7/4/'스테이지별 골드'!$M$5) -> 22.971698
A8: 산업 | B8: =SUMIF('스테이지별 골드'!$A$5:$A$32,A8,'스테이지별 골드'!$M$5:$M$32) -> 26761 | C8: =SUMIF('스테이지별 골드'!$A$5:$A$32,A8,'스테이지별 골드'!$Q$5:$Q$32) -> 50431 | D8: =B8+C8 -> 77192 | E8: =IF($D$12=0,0,D8/$D$12) -> 0.036620455 | F8: =IF('스테이지별 골드'!$M$5=0,0,B8/4/'스테이지별 골드'!$M$5) -> 63.115566
A9: 현대 | B9: =SUMIF('스테이지별 골드'!$A$5:$A$32,A9,'스테이지별 골드'!$M$5:$M$32) -> 71560 | C9: =SUMIF('스테이지별 골드'!$A$5:$A$32,A9,'스테이지별 골드'!$Q$5:$Q$32) -> 128070 | D9: =B9+C9 -> 199630 | E9: =IF($D$12=0,0,D9/$D$12) -> 0.094705946 | F9: =IF('스테이지별 골드'!$M$5=0,0,B9/4/'스테이지별 골드'!$M$5) -> 168.77358
A10: 미래 | B10: =SUMIF('스테이지별 골드'!$A$5:$A$32,A10,'스테이지별 골드'!$M$5:$M$32) -> 187496 | C10: =SUMIF('스테이지별 골드'!$A$5:$A$32,A10,'스테이지별 골드'!$Q$5:$Q$32) -> 322605 | D10: =B10+C10 -> 510101 | E10: =IF($D$12=0,0,D10/$D$12) -> 0.24199568 | F10: =IF('스테이지별 골드'!$M$5=0,0,B10/4/'스테이지별 골드'!$M$5) -> 442.20755
A11: 우주 | B11: =SUMIF('스테이지별 골드'!$A$5:$A$32,A11,'스테이지별 골드'!$M$5:$M$32) -> 478741 | C11: =SUMIF('스테이지별 골드'!$A$5:$A$32,A11,'스테이지별 골드'!$Q$5:$Q$32) -> 798300 | D11: =B11+C11 -> 1277041 | E11: =IF($D$12=0,0,D11/$D$12) -> 0.60583768 | F11: =IF('스테이지별 골드'!$M$5=0,0,B11/4/'스테이지별 골드'!$M$5) -> 1129.1061
A12: 합계 | B12: =SUM(B5:B11) -> 778681 | C12: =SUM(C5:C11) -> 1329212 | D12: =SUM(D5:D11) -> 2107893 | E12: =SUM(E5:E11) -> 1
A14: 주요 지표
A15: 1-1 스테이지 골드 (보너스 제외) | B15: ='스테이지별 골드'!M5 -> 106
A16: 7-4 스테이지 골드 (보너스 제외) | B16: ='스테이지별 골드'!M32 -> 173940
A17: 1-1 일반 건물 1개 골드 | B17: ='스테이지별 골드'!J5 -> 10
A18: 7-4 랜드마크 골드 | B18: ='스테이지별 골드'!L32 -> 19500
A19: 전 스테이지 1회 클리어 누적 골드 (보너스 포함) | B19: ='스테이지별 골드'!S32 -> 2107893
A20: 건물 1개 최대 드랍 개수 | B20: =MAX('드랍 구성'!K5:K102) -> 29
A21: 건물 1개 최소 드랍 개수 | B21: =MIN('드랍 구성'!K5:K102) -> 6

Sheet 개편안 설명
A1: 드랍 재배치 개편안 (Ver03): 인크리멘탈 문법에 맞춘 재화 성장 설계
A2: 기준: 20261001_레벨디자인_Ver03_백승오 (건물 수·체력·보너스 스테이지) / Ver02 드랍 구성 분석 결과. 원본 시트(드랍 구성·스테이지별 골드)는 수정하지 않고 비교용으로 남김.
A5: Ver02의 문제
A6: ① 상위 재화가 해금되는 순간 드랍 개수가 급감함 (예: 일반 4-1 금괴 24개 → 4-2 사파이어 6개). 보상은 +25%인데 화면은 1/4로 줄어듦
A7: ② 잔돈(코인 1~4개)이 불규칙하게 섞여 시각적 노이즈가 생김. 7-1 공격 건물은 루비 21개 + 코인 4개(전체의 0.2%)
A8: ③ 재화 등장 시점이 "골드 ≥ 등급 × 5"라는 산술 조건에 끌려가서, 허들이나 시대 전환 같은 게임 이벤트와 연결되지 않음
A10: 설계 원칙 (인크리멘탈 장르 문법)
A11: 1. 숫자는 항상 커진다: 건물 1개 드랍 개수가 스테이지마다 늘거나 유지됨 (감소 0회). 새 시대에 들어서면 한 단계 더 늘어남
A12: 2. 교체가 아니라 섞여 들어온다: 인접 2등급만 섞고, 상위 재화 비중이 스테이지마다 점점 커짐. 잔돈 재화 없음
A13: 3. 신규 재화 = 허들 돌파 보상: 홀수 시대 보스(1-4 / 3-4 / 5-4 / 7-4)에서 사파이어 / 루비 / 다이아몬드 / 왕관이 처음 등장
A14: 4. 짝수 시대 보스(2-4 / 4-4 / 6-4)에서는 그 재화가 골드 비중 기준 주력으로 승격됨 (개수로는 40~50%) → 시대마다 재화 쪽 사건이 1번씩 생김
A15: 5. 건물 위계 = 재화 위계: 신규 재화는 랜드마크 → 황금 → 공격 → 일반 순서로 1~3시대에 걸쳐 내려옴 (상위 건물이 다음 재화를 미리 보여 줌)
... A38: 레벨디자인 문서 p05(프랑스 → 독일)와 p07~p09(독일 → 프랑스)의 중세 지역 순서가 서로 다름. 스테이지별 골드 시트는 p05 순서를 따름

Sheet 개편 요약
A1: 드랍 재배치 개편 요약 (Ver02 → Ver03)
A2: 모든 값은 수식. 설정 시트의 개편안 입력값을 바꾸면 갱신됨.
A4: 1. 재화별 첫 등장 스테이지 (신규 재화 = 대허들 돌파 보상)
A5: 건물 유형 | B5: 금 코인 | C5: 금괴 | D5: 사파이어 | E5: 루비 | F5: 다이아몬드 | G5: 왕관
A6: 일반 | B6: =IFERROR(INDEX('드랍 구성 (개편)'!$B$5:$B$32,MATCH(TRUE,INDEX('드랍 구성 (개편)'!$U$5:$U$32>0,0),0)),"—") -> 1-1 | C6: =IFERROR(INDEX('드랍 구성 (개편)'!$B$5:$B$32,MATCH(TRUE,INDEX('드랍 구성 (개편)'!$T$5:$T$32>0,0),0)),"—") -> 1-2 | D6: =IFERROR(INDEX('드랍 구성 (개편)'!$B$5:$B$32,MATCH(TRUE,INDEX('드랍 구성 (개편)'!$S$5:$S$32>0,0),0)),"—") -> 3-3 | E6: =IFERROR(INDEX('드랍 구성 (개편)'!$B$5:$B$32,MATCH(TRUE,INDEX('드랍 구성 (개편)'!$R$5:$R$32>0,0),0)),"—") -> 6-1 | F6: =IFERROR(INDEX('드랍 구성 (개편)'!$B$5:$B$32,MATCH(TRUE,INDEX('드랍 구성 (개편)'!$Q$5:$Q$32>0,0),0)),"—") -> — | G6: =IFERROR(INDEX('드랍 구성 (개편)'!$B$5:$B$32,MATCH(TRUE,INDEX('드랍 구성 (개편)'!$P$5:$P$32>0,0),0)),"—") -> —
A7: 공격 | B7: =IFERROR(INDEX('드랍 구성 (개편)'!$B$33:$B$60,MATCH(TRUE,INDEX('드랍 구성 (개편)'!$U$33:$U$60>0,0),0)),"—") -> 1-1 | C7: =IFERROR(INDEX('드랍 구성 (개편)'!$B$33:$B$60,MATCH(TRUE,INDEX('드랍 구성 (개편)'!$T$33:$T$60>0,0),0)),"—") -> 1-1 | D7: =IFERROR(INDEX('드랍 구성 (개편)'!$B$33:$B$60,MATCH(TRUE,INDEX('드랍 구성 (개편)'!$S$33:$S$60>0,0),0)),"—") -> 3-2 | E7: =IFERROR(INDEX('드랍 구성 (개편)'!$B$33:$B$60,MATCH(TRUE,INDEX('드랍 구성 (개편)'!$R$33:$R$60>0,0),0)),"—") -> 5-3 | F7: =IFERROR(INDEX('드랍 구성 (개편)'!$B$33:$B$60,MATCH(TRUE,INDEX('드랍 구성 (개편)'!$Q$33:$Q$60>0,0),0)),"—") -> 7-3 | G7: =IFERROR(INDEX('드랍 구성 (개편)'!$B$33:$B$60,MATCH(TRUE,INDEX('드랍 구성 (개편)'!$P$33:$P$60>0,0),0)),"—") -> —
A8: 랜드마크 | B8: =IFERROR(INDEX('드랍 구성 (개편)'!$B$61:$B$74,MATCH(TRUE,INDEX('드랍 구성 (개편)'!$U$61:$U$74>0,0),0)),"—") -> 1-2 | C8: =IFERROR(INDEX('드랍 구성 (개편)'!$B$61:$B$74,MATCH(TRUE,INDEX('드랍 구성 (개편)'!$T$61:$T$74>0,0),0)),"—") -> 1-2 | D8: =IFERROR(INDEX('드랍 구성 (개편)'!$B$61:$B$74,MATCH(TRUE,INDEX('드랍 구성 (개편)'!$S$61:$S$74>0,0),0)),"—") -> 1-4 | E8: =IFERROR(INDEX('드랍 구성 (개편)'!$B$61:$B$74,MATCH(TRUE,INDEX('드랍 구성 (개편)'!$R$61:$R$74>0,0),0)),"—") -> 3-4 | F8: =IFERROR(INDEX('드랍 구성 (개편)'!$B$61:$B$74,MATCH(TRUE,INDEX('드랍 구성 (개편)'!$Q$61:$Q$74>0,0),0)),"—") -> 5-4 | G8: =IFERROR(INDEX('드랍 구성 (개편)'!$B$61:$B$74,MATCH(TRUE,INDEX('드랍 구성 (개편)'!$P$61:$P$74>0,0),0)),"—") -> 7-4
A9: 황금 (보너스) | B9: =IFERROR(INDEX('드랍 구성 (개편)'!$B$75:$B$102,MATCH(TRUE,INDEX('드랍 구성 (개편)'!$U$75:$U$102>0,0),0)),"—") -> 1-1 | C9: =IFERROR(INDEX('드랍 구성 (개편)'!$B$75:$B$102,MATCH(TRUE,INDEX('드랍 구성 (개편)'!$T$75:$T$102>0,0),0)),"—") -> 1-1 | D9: =IFERROR(INDEX('드랍 구성 (개편)'!$B$75:$B$102,MATCH(TRUE,INDEX('드랍 구성 (개편)'!$S$75:$S$102>0,0),0)),"—") -> 2-2 | E9: =IFERROR(INDEX('드랍 구성 (개편)'!$B$75:$B$102,MATCH(TRUE,INDEX('드랍 구성 (개편)'!$R$75:$R$102>0,0),0)),"—") -> 4-3 | F9: =IFERROR(INDEX('드랍 구성 (개편)'!$B$75:$B$102,MATCH(TRUE,INDEX('드랍 구성 (개편)'!$Q$75:$Q$102>0,0),0)),"—") -> 6-3 | G9: =IFERROR(INDEX('드랍 구성 (개편)'!$B$75:$B$102,MATCH(TRUE,INDEX('드랍 구성 (개편)'!$P$75:$P$102>0,0),0)),"—") -> —
A11: 2. 건물 1개 드랍 개수 비교
A12: 건물 유형 | B12: Ver02 최소 | C12: Ver02 최대 | D12: Ver02 개수 감소 횟수 | E12: Ver03 최소 | F12: Ver03 최대 | G12: Ver03 개수 감소 횟수 | H12: Ver03 1-1→7-4 증가 배수 | I12: Ver03 최대 골드 오차
A13: 일반 | B13: =MIN('드랍 구성 (개편)'!$Z$5:$Z$32) -> 6 | C13: =MAX('드랍 구성 (개편)'!$Z$5:$Z$32) -> 24 | D13: =SUMPRODUCT(--('드랍 구성 (개편)'!$Z$6:$Z$32<'드랍 구성 (개편)'!$Z$5:$Z$31)) -> 7 | E13: =MIN('드랍 구성 (개편)'!$V$5:$V$32) -> 10 | F13: =MAX('드랍 구성 (개편)'!$V$5:$V$32) -> 26 | G13: =SUMPRODUCT(--('드랍 구성 (개편)'!$V$6:$V$32<'드랍 구성 (개편)'!$V$5:$V$31)) -> 0 | H13: ='드랍 구성 (개편)'!$V$32/'드랍 구성 (개편)'!$V$5 -> 2.6 | I13: =MAX(INDEX(ABS('드랍 구성 (개편)'!$X$5:$X$32),0)) -> 0.125
A14: 공격 | B14: =MIN('드랍 구성 (개편)'!$Z$33:$Z$60) -> 6 | C14: =MAX('드랍 구성 (개편)'!$Z$33:$Z$60) -> 29 | D14: =SUMPRODUCT(--('드랍 구성 (개편)'!$Z$34:$Z$60<'드랍 구성 (개편)'!$Z$33:$Z$59)) -> 6 | E14: =MIN('드랍 구성 (개편)'!$V$33:$V$60) -> 12 | F14: =MAX('드랍 구성 (개편)'!$V$33:$V$60) -> 31 | G14: =SUMPRODUCT(--('드랍 구성 (개편)'!$V$34:$V$60<'드랍 구성 (개편)'!$V$33:$V$59)) -> 0 | H14: ='드랍 구성 (개편)'!$V$60/'드랍 구성 (개편)'!$V$33 -> 2.5833333 | I14: =MAX(INDEX(ABS('드랍 구성 (개편)'!$X$33:$X$60),0)) -> 0.057692308
A15: 랜드마크 | B15: =MIN('드랍 구성 (개편)'!$Z$61:$Z$74) -> 7 | C15: =MAX('드랍 구성 (개편)'!$Z$61:$Z$74) -> 24 | D15: =SUMPRODUCT(--('드랍 구성 (개편)'!$Z$62:$Z$74<'드랍 구성 (개편)'!$Z$61:$Z$73)) -> 3 | E15: =MIN('드랍 구성 (개편)'!$V$61:$V$74) -> 20 | F15: =MAX('드랍 구성 (개편)'!$V$61:$V$74) -> 37 | G15: =SUMPRODUCT(--('드랍 구성 (개편)'!$V$62:$V$74<'드랍 구성 (개편)'!$V$61:$V$73)) -> 0 | H15: ='드랍 구성 (개편)'!$V$74/'드랍 구성 (개편)'!$V$61 -> 1.85 | I15: =MAX(INDEX(ABS('드랍 구성 (개편)'!$X$61:$X$74),0)) -> 0.036697248
A16: 황금 (보너스) | B16: =MIN('드랍 구성 (개편)'!$Z$75:$Z$102) -> 7 | C16: =MAX('드랍 구성 (개편)'!$Z$75:$Z$102) -> 29 | D16: =SUMPRODUCT(--('드랍 구성 (개편)'!$Z$76:$Z$102<'드랍 구성 (개편)'!$Z$75:$Z$101)) -> 8 | E16: =MIN('드랍 구성 (개편)'!$V$75:$V$102) -> 18 | F16: =MAX('드랍 구성 (개편)'!$V$75:$V$102) -> 44 | G16: =SUMPRODUCT(--('드랍 구성 (개편)'!$V$76:$V$102<'드랍 구성 (개편)'!$V$75:$V$101)) -> 0 | H16: ='드랍 구성 (개편)'!$V$102/'드랍 구성 (개편)'!$V$75 -> 2.4444444 | I16: =MAX(INDEX(ABS('드랍 구성 (개편)'!$X$75:$X$102),0)) -> 0.045801527
A17: 전체 골드 오차 (확정 골드 합 ÷ 목표 골드 합 - 1) | F17: =SUM('드랍 구성 (개편)'!$AB$5:$AB$102)/SUMPRODUCT('드랍 구성 (개편)'!$E$5:$E$102,'드랍 구성 (개편)'!$F$5:$F$102)-1 -> 0.0014355567
A19: 3. 스테이지별 드랍 개수 · 주력 재화
A20: 스테이지 | B20: 허들 등급 | C20: 일반 개수 | D20: 공격 개수 | E20: 랜드마크 개수 | F20: 황금 개수 | G20: Ver02 일반 개수 | H20: 일반 주력 | I20: 공격 주력 | J20: 랜드마크 주력 | K20: 황금 주력 | L20: 신규 재화 데뷔
A21: ='스테이지별 골드'!C5 -> 1-1 | B21: ='허들 설계'!F5 -> 튜토리얼 | C21: =IFERROR(INDEX('드랍 구성 (개편)'!$V$5:$V$32,MATCH($A21,'드랍 구성 (개편)'!$B$5:$B$32,0)),"—") -> 10 | D21: =IFERROR(INDEX('드랍 구성 (개편)'!$V$33:$V$60,MATCH($A21,'드랍 구성 (개편)'!$B$33:$B$60,0)),"—") -> 12 | E21: =IFERROR(INDEX('드랍 구성 (개편)'!$V$61:$V$74,MATCH($A21,'드랍 구성 (개편)'!$B$61:$B$74,0)),"—") -> — | F21: =IFERROR(INDEX('드랍 구성 (개편)'!$V$75:$V$102,MATCH($A21,'드랍 구성 (개편)'!$B$75:$B$102,0)),"—") -> 18 | G21: =IFERROR(INDEX('드랍 구성 (개편)'!$Z$5:$Z$32,MATCH($A21,'드랍 구성 (개편)'!$B$5:$B$32,0)),"—") -> 10 | H21: =IFERROR(INDEX('드랍 구성 (개편)'!$Y$5:$Y$32,MATCH($A21,'드랍 구성 (개편)'!$B$5:$B$32,0)),"—") -> 금 코인 | I21: =IFERROR(INDEX('드랍 구성 (개편)'!$Y$33:$Y$60,MATCH($A21,'드랍 구성 (개편)'!$B$33:$B$60,0)),"—") -> 금 코인 | J21: =IFERROR(INDEX('드랍 구성 (개편)'!$Y$61:$Y$74,MATCH($A21,'드랍 구성 (개편)'!$B$61:$B$74,0)),"—") -> — | K21: =IFERROR(INDEX('드랍 구성 (개편)'!$Y$75:$Y$102,MATCH($A21,'드랍 구성 (개편)'!$B$75:$B$102,0)),"—") -> 금괴 | L21: ='허들 설계'!R5 -> 금 코인 · 금괴 (기본)
A22: ='스테이지별 골드'!C6 -> 1-2 | B22: ='허들 설계'!F6 -> 소허들 | C22: =IFERROR(INDEX('드랍 구성 (개편)'!$V$5:$V$32,MATCH($A22,'드랍 구성 (개편)'!$B$5:$B$32,0)),"—") -> 10 | D22: =IFERROR(INDEX('드랍 구성 (개편)'!$V$33:$V$60,MATCH($A22,'드랍 구성 (개편)'!$B$33:$B$60,0)),"—") -> 12 | E22: =IFERROR(INDEX('드랍 구성 (개편)'!$V$61:$V$74,MATCH($A22,'드랍 구성 (개편)'!$B$61:$B$74,0)),"—") -> 20 | F22: =IFERROR(INDEX('드랍 구성 (개편)'!$V$75:$V$102,MATCH($A22,'드랍 구성 (개편)'!$B$75:$B$102,0)),"—") -> 18 | G22: =IFERROR(INDEX('드랍 구성 (개편)'!$Z$5:$Z$32,MATCH($A22,'드랍 구성 (개편)'!$B$5:$B$32,0)),"—") -> 13 | H22: =IFERROR(INDEX('드랍 구성 (개편)'!$Y$5:$Y$32,MATCH($A22,'드랍 구성 (개편)'!$B$5:$B$32,0)),"—") -> 금 코인 | I22: =IFERROR(INDEX('드랍 구성 (개편)'!$Y$33:$Y$60,MATCH($A22,'드랍 구성 (개편)'!$B$33:$B$60,0)),"—") -> 금괴 | J22: =IFERROR(INDEX('드랍 구성 (개편)'!$Y$61:$Y$74,MATCH($A22,'드랍 구성 (개편)'!$B$61:$B$74,0)),"—") -> 금괴 | K22: =IFERROR(INDEX('드랍 구성 (개편)'!$Y$75:$Y$102,MATCH($A22,'드랍 구성 (개편)'!$B$75:$B$102,0)),"—") -> 금괴 | L22: ='허들 설계'!R6
A23: ='스테이지별 골드'!C7 -> 1-3 | B23: ='허들 설계'!F7 -> 평탄 | C23: =IFERROR(INDEX('드랍 구성 (개편)'!$V$5:$V$32,MATCH($A23,'드랍 구성 (개편)'!$B$5:$B$32,0)),"—") -> 10 | D23: =IFERROR(INDEX('드랍 구성 (개편)'!$V$33:$V$60,MATCH($A23,'드랍 구성 (개편)'!$B$33:$B$60,0)),"—") -> 12 | E23: =IFERROR(INDEX('드랍 구성 (개편)'!$V$61:$V$74,MATCH($A23,'드랍 구성 (개편)'!$B$61:$B$74,0)),"—") -> — | F23: =IFERROR(INDEX('드랍 구성 (개편)'!$V$75:$V$102,MATCH($A23,'드랍 구성 (개편)'!$B$75:$B$102,0)),"—") -> 19 | G23: =IFERROR(INDEX('드랍 구성 (개편)'!$Z$5:$Z$32,MATCH($A23,'드랍 구성 (개편)'!$B$5:$B$32,0)),"—") -> 15 | H23: =IFERROR(INDEX('드랍 구성 (개편)'!$Y$5:$Y$32,MATCH($A23,'드랍 구성 (개편)'!$B$5:$B$32,0)),"—") -> 금 코인 | I23: =IFERROR(INDEX('드랍 구성 (개편)'!$Y$33:$Y$60,MATCH($A23,'드랍 구성 (개편)'!$B$33:$B$60,0)),"—") -> 금괴 | J23: =IFERROR(INDEX('드랍 구성 (개편)'!$Y$61:$Y$74,MATCH($A23,'드랍 구성 (개편)'!$B$61:$B$74,0)),"—") -> — | K23: =IFERROR(INDEX('드랍 구성 (개편)'!$Y$75:$Y$102,MATCH($A23,'드랍 구성 (개편)'!$B$75:$B$102,0)),"—") -> 금괴 | L23: ='허들 설계'!R7
A24: ='스테이지별 골드'!C8 -> 1-4 | B24: ='허들 설계'!F8 -> 대허들 | C24: =IFERROR(INDEX('드랍 구성 (개편)'!$V$5:$V$32,MATCH($A24,'드랍 구성 (개편)'!$B$5:$B$32,0)),"—") -> 11 | D24: =IFERROR(INDEX('드랍 구성 (개편)'!$V$33:$V$60,MATCH($A24,'드랍 구성 (개편)'!$B$33:$B$60,0)),"—") -> 13 | E24: =IFERROR(INDEX('드랍 구성 (개편)'!$V$61:$V$74,MATCH($A24,'드랍 구성 (개편)'!$B$61:$B$74,0)),"—") -> 21 | F24: =IFERROR(INDEX('드랍 구성 (개편)'!$V$75:$V$102,MATCH($A24,'드랍 구성 (개편)'!$B$75:$B$102,0)),"—") -> 19 | G24: =IFERROR(INDEX('드랍 구성 (개편)'!$Z$5:$Z$32,MATCH($A24,'드랍 구성 (개편)'!$B$5:$B$32,0)),"—") -> 19 | H24: =IFERROR(INDEX('드랍 구성 (개편)'!$Y$5:$Y$32,MATCH($A24,'드랍 구성 (개편)'!$B$5:$B$32,0)),"—") -> 금괴 | I24: =IFERROR(INDEX('드랍 구성 (개편)'!$Y$33:$Y$60,MATCH($A24,'드랍 구성 (개편)'!$B$33:$B$60,0)),"—") -> 금괴 | J24: =IFERROR(INDEX('드랍 구성 (개편)'!$Y$61:$Y$74,MATCH($A24,'드랍 구성 (개편)'!$B$61:$B$74,0)),"—") -> 금괴 | K24: =IFERROR(INDEX('드랍 구성 (개편)'!$Y$75:$Y$102,MATCH($A24,'드랍 구성 (개편)'!$B$75:$B$102,0)),"—") -> 금괴 | L24: ='허들 설계'!R8 -> 사파이어
A25: ='스테이지별 골드'!C9 -> 2-1 | B25: ='허들 설계'!F9 -> 돌파 | C25: =IFERROR(INDEX('드랍 구성 (개편)'!$V$5:$V$32,MATCH($A25,'드랍 구성 (개편)'!$B$5:$B$32,0)),"—") -> 12 | D25: =IFERROR(INDEX('드랍 구성 (개편)'!$V$33:$V$60,MATCH($A25,'드랍 구성 (개편)'!$B$33:$B$60,0)),"—") -> 14 | E25: =IFERROR(INDEX('드랍 구성 (개편)'!$V$61:$V$74,MATCH($A25,'드랍 구성 (개편)'!$B$61:$B$74,0)),"—") -> — | F25: =IFERROR(INDEX('드랍 구성 (개편)'!$V$75:$V$102,MATCH($A25,'드랍 구성 (개편)'!$B$75:$B$102,0)),"—") -> 21 | G25: =IFERROR(INDEX('드랍 구성 (개편)'!$Z$5:$Z$32,MATCH($A25,'드랍 구성 (개편)'!$B$5:$B$32,0)),"—") -> 23 | H25: =IFERROR(INDEX('드랍 구성 (개편)'!$Y$5:$Y$32,MATCH($A25,'드랍 구성 (개편)'!$B$5:$B$32,0)),"—") -> 금괴 | I25: =IFERROR(INDEX('드랍 구성 (개편)'!$Y$33:$Y$60,MATCH($A25,'드랍 구성 (개편)'!$B$33:$B$60,0)),"—") -> 금괴 | J25: =IFERROR(INDEX('드랍 구성 (개편)'!$Y$61:$Y$74,MATCH($A25,'드랍 구성 (개편)'!$B$61:$B$74,0)),"—") -> — | K25: =IFERROR(INDEX('드랍 구성 (개편)'!$Y$75:$Y$102,MATCH($A25,'드랍 구성 (개편)'!$B$75:$B$102,0)),"—") -> 금괴 | L25: ='허들 설계'!R9
A26: ='스테이지별 골드'!C10 -> 2-2 | B26: ='허들 설계'!F10 -> 소허들 | C26: =IFERROR(INDEX('드랍 구성 (개편)'!$V$5:$V$32,MATCH($A26,'드랍 구성 (개편)'!$B$5:$B$32,0)),"—") -> 12 | D26: =IFERROR(INDEX('드랍 구성 (개편)'!$V$33:$V$60,MATCH($A26,'드랍 구성 (개편)'!$B$33:$B$60,0)),"—") -> 14 | E26: =IFERROR(INDEX('드랍 구성 (개편)'!$V$61:$V$74,MATCH($A26,'드랍 구성 (개편)'!$B$61:$B$74,0)),"—") -> 22 | F26: =IFERROR(INDEX('드랍 구성 (개편)'!$V$75:$V$102,MATCH($A26,'드랍 구성 (개편)'!$B$75:$B$102,0)),"—") -> 21 | G26: =IFERROR(INDEX('드랍 구성 (개편)'!$Z$5:$Z$32,MATCH($A26,'드랍 구성 (개편)'!$B$5:$B$32,0)),"—") -> 9 | H26: =IFERROR(INDEX('드랍 구성 (개편)'!$Y$5:$Y$32,MATCH($A26,'드랍 구성 (개편)'!$B$5:$B$32,0)),"—") -> 금괴 | I26: =IFERROR(INDEX('드랍 구성 (개편)'!$Y$33:$Y$60,MATCH($A26,'드랍 구성 (개편)'!$B$33:$B$60,0)),"—") -> 금괴 | J26: =IFERROR(INDEX('드랍 구성 (개편)'!$Y$61:$Y$74,MATCH($A26,'드랍 구성 (개편)'!$B$61:$B$74,0)),"—") -> 사파이어 | K26: =IFERROR(INDEX('드랍 구성 (개편)'!$Y$75:$Y$102,MATCH($A26,'드랍 구성 (개편)'!$B$75:$B$102,0)),"—") -> 금괴 | L26: ='허들 설계'!R10
A27: ='스테이지별 골드'!C11 -> 2-3 | B27: ='허들 설계'!F11 -> 평탄 | C27: =IFERROR(INDEX('드랍 구성 (개편)'!$V$5:$V$32,MATCH($A27,'드랍 구성 (개편)'!$B$5:$B$32,0)),"—") -> 12 | D27: =IFERROR(INDEX('드랍 구성 (개편)'!$V$33:$V$60,MATCH($A27,'드랍 구성 (개편)'!$B$33:$B$60,0)),"—") -> 14 | E27: =IFERROR(INDEX('드랍 구성 (개편)'!$V$61:$V$74,MATCH($A27,'드랍 구성 (개편)'!$B$61:$B$74,0)),"—") -> — | F27: =IFERROR(INDEX('드랍 구성 (개편)'!$V$75:$V$102,MATCH($A27,'드랍 구성 (개편)'!$B$75:$B$102,0)),"—") -> 21 | G27: =IFERROR(INDEX('드랍 구성 (개편)'!$Z$5:$Z$32,MATCH($A27,'드랍 구성 (개편)'!$B$5:$B$32,0)),"—") -> 7 | H27: =IFERROR(INDEX('드랍 구성 (개편)'!$Y$5:$Y$32,MATCH($A27,'드랍 구성 (개편)'!$B$5:$B$32,0)),"—") -> 금괴 | I27: =IFERROR(INDEX('드랍 구성 (개편)'!$Y$33:$Y$60,MATCH($A27,'드랍 구성 (개편)'!$B$33:$B$60,0)),"—") -> 금괴 | J27: =IFERROR(INDEX('드랍 구성 (개편)'!$Y$61:$Y$74,MATCH($A27,'드랍 구성 (개편)'!$B$61:$B$74,0)),"—") -> — | K27: =IFERROR(INDEX('드랍 구성 (개편)'!$Y$75:$Y$102,MATCH($A27,'드랍 구성 (개편)'!$B$75:$B$102,0)),"—") -> 금괴 | L27: ='허들 설계'!R11
A28: ='스테이지별 골드'!C12 -> 2-4 | B28: ='허들 설계'!F12 -> 대허들 | C28: =IFERROR(INDEX('드랍 구성 (개편)'!$V$5:$V$32,MATCH($A28,'드랍 구성 (개편)'!$B$5:$B$32,0)),"—") -> 12 | D28: =IFERROR(INDEX('드랍 구성 (개편)'!$V$33:$V$60,MATCH($A28,'드랍 구성 (개편)'!$B$33:$B$60,0)),"—") -> 15 | E28: =IFERROR(INDEX('드랍 구성 (개편)'!$V$61:$V$74,MATCH($A28,'드랍 구성 (개편)'!$B$61:$B$74,0)),"—") -> 23 | F28: =IFERROR(INDEX('드랍 구성 (개편)'!$V$75:$V$102,MATCH($A28,'드랍 구성 (개편)'!$B$75:$B$102,0)),"—") -> 22 | G28: =IFERROR(INDEX('드랍 구성 (개편)'!$Z$5:$Z$32,MATCH($A28,'드랍 구성 (개편)'!$B$5:$B$32,0)),"—") -> 12 | H28: =IFERROR(INDEX('드랍 구성 (개편)'!$Y$5:$Y$32,MATCH($A28,'드랍 구성 (개편)'!$B$5:$B$32,0)),"—") -> 금괴 | I28: =IFERROR(INDEX('드랍 구성 (개편)'!$Y$33:$Y$60,MATCH($A28,'드랍 구성 (개편)'!$B$33:$B$60,0)),"—") -> 금괴 | J28: =IFERROR(INDEX('드랍 구성 (개편)'!$Y$61:$Y$74,MATCH($A28,'드랍 구성 (개편)'!$B$61:$B$74,0)),"—") -> 사파이어 | K28: =IFERROR(INDEX('드랍 구성 (개편)'!$Y$75:$Y$102,MATCH($A28,'드랍 구성 (개편)'!$B$75:$B$102,0)),"—") -> 사파이어 | L28: ='허들 설계'!R12
A29: ='스테이지별 골드'!C13 -> 3-1 | B29: ='허들 설계'!F13 -> 돌파 | C29: =IFERROR(INDEX('드랍 구성 (개편)'!$V$5:$V$32,MATCH($A29,'드랍 구성 (개편)'!$B$5:$B$32,0)),"—") -> 13 | D29: =IFERROR(INDEX('드랍 구성 (개편)'!$V$33:$V$60,MATCH($A29,'드랍 구성 (개편)'!$B$33:$B$60,0)),"—") -> 16 | E29: =IFERROR(INDEX('드랍 구성 (개편)'!$V$61:$V$74,MATCH($A29,'드랍 구성 (개편)'!$B$61:$B$74,0)),"—") -> — | F29: =IFERROR(INDEX('드랍 구성 (개편)'!$V$75:$V$102,MATCH($A29,'드랍 구성 (개편)'!$B$75:$B$102,0)),"—") -> 24 | G29: =IFERROR(INDEX('드랍 구성 (개편)'!$Z$5:$Z$32,MATCH($A29,'드랍 구성 (개편)'!$B$5:$B$32,0)),"—") -> 13 | H29: =IFERROR(INDEX('드랍 구성 (개편)'!$Y$5:$Y$32,MATCH($A29,'드랍 구성 (개편)'!$B$5:$B$32,0)),"—") -> 금괴 | I29: =IFERROR(INDEX('드랍 구성 (개편)'!$Y$33:$Y$60,MATCH($A29,'드랍 구성 (개편)'!$B$33:$B$60,0)),"—") -> 금괴 | J29: =IFERROR(INDEX('드랍 구성 (개편)'!$Y$61:$Y$74,MATCH($A29,'드랍 구성 (개편)'!$B$61:$B$74,0)),"—") -> — | K29: =IFERROR(INDEX('드랍 구성 (개편)'!$Y$75:$Y$102,MATCH($A29,'드랍 구성 (개편)'!$B$75:$B$102,0)),"—") -> 사파이어 | L29: ='허들 설계'!R13
A30: ='스테이지별 골드'!C14 -> 3-2 | B30: ='허들 설계'!F14 -> 소허들 | C30: =IFERROR(INDEX('드랍 구성 (개편)'!$V$5:$V$32,MATCH($A30,'드랍 구성 (개편)'!$B$5:$B$32,0)),"—") -> 14 | D30: =IFERROR(INDEX('드랍 구성 (개편)'!$V$33:$V$60,MATCH($A30,'드랍 구성 (개편)'!$B$33:$B$60,0)),"—") -> 16 | E30: =IFERROR(INDEX('드랍 구성 (개편)'!$V$61:$V$74,MATCH($A30,'드랍 구성 (개편)'!$B$61:$B$74,0)),"—") -> 25 | F30: =IFERROR(INDEX('드랍 구성 (개편)'!$V$75:$V$102,MATCH($A30,'드랍 구성 (개편)'!$B$75:$B$102,0)),"—") -> 24 | G30: =IFERROR(INDEX('드랍 구성 (개편)'!$Z$5:$Z$32,MATCH($A30,'드랍 구성 (개편)'!$B$5:$B$32,0)),"—") -> 14 | H30: =IFERROR(INDEX('드랍 구성 (개편)'!$Y$5:$Y$32,MATCH($A30,'드랍 구성 (개편)'!$B$5:$B$32,0)),"—") -> 금괴 | I30: =IFERROR(INDEX('드랍 구성 (개편)'!$Y$33:$Y$60,MATCH($A30,'드랍 구성 (개편)'!$B$33:$B$60,0)),"—") -> 금괴 | J30: =IFERROR(INDEX('드랍 구성 (개편)'!$Y$61:$Y$74,MATCH($A30,'드랍 구성 (개편)'!$B$61:$B$74,0)),"—") -> 사파이어 | K30: =IFERROR(INDEX('드랍 구성 (개편)'!$Y$75:$Y$102,MATCH($A30,'드랍 구성 (개편)'!$B$75:$B$102,0)),"—") -> 사파이어 | L30: ='허들 설계'!R14
A31: ='스테이지별 골드'!C15 -> 3-3 | B31: ='허들 설계'!F15 -> 평탄 | C31: =IFERROR(INDEX('드랍 구성 (개편)'!$V$5:$V$32,MATCH($A31,'드랍 구성 (개편)'!$B$5:$B$32,0)),"—") -> 14 | D31: =IFERROR(INDEX('드랍 구성 (개편)'!$V$33:$V$60,MATCH($A31,'드랍 구성 (개편)'!$B$33:$B$60,0)),"—") -> 17 | E31: =IFERROR(INDEX('드랍 구성 (개편)'!$V$61:$V$74,MATCH($A31,'드랍 구성 (개편)'!$B$61:$B$74,0)),"—") -> — | F31: =IFERROR(INDEX('드랍 구성 (개편)'!$V$75:$V$102,MATCH($A31,'드랍 구성 (개편)'!$B$75:$B$102,0)),"—") -> 25 | G31: =IFERROR(INDEX('드랍 구성 (개편)'!$Z$5:$Z$32,MATCH($A31,'드랍 구성 (개편)'!$B$5:$B$32,0)),"—") -> 16 | H31: =IFERROR(INDEX('드랍 구성 (개편)'!$Y$5:$Y$32,MATCH($A31,'드랍 구성 (개편)'!$B$5:$B$32,0)),"—") -> 금괴 | I31: =IFERROR(INDEX('드랍 구성 (개편)'!$Y$33:$Y$60,MATCH($A31,'드랍 구성 (개편)'!$B$33:$B$60,0)),"—") -> 금괴 | J31: =IFERROR(INDEX('드랍 구성 (개편)'!$Y$61:$Y$74,MATCH($A31,'드랍 구성 (개편)'!$B$61:$B$74,0)),"—") -> — | K31: =IFERROR(INDEX('드랍 구성 (개편)'!$Y$75:$Y$102,MATCH($A31,'드랍 구성 (개편)'!$B$75:$B$102,0)),"—") -> 사파이어 | L31: ='허들 설계'!R15
A32: ='스테이지별 골드'!C16 -> 3-4 | B32: ='허들 설계'!F16 -> 대허들 | C32: =IFERROR(INDEX('드랍 구성 (개편)'!$V$5:$V$32,MATCH($A32,'드랍 구성 (개편)'!$B$5:$B$32,0)),"—") -> 14 | D32: =IFERROR(INDEX('드랍 구성 (개편)'!$V$33:$V$60,MATCH($A32,'드랍 구성 (개편)'!$B$33:$B$60,0)),"—") -> 17 | E32: =IFERROR(INDEX('드랍 구성 (개편)'!$V$61:$V$74,MATCH($A32,'드랍 구성 (개편)'!$B$61:$B$74,0)),"—") -> 25 | F32: =IFERROR(INDEX('드랍 구성 (개편)'!$V$75:$V$102,MATCH($A32,'드랍 구성 (개편)'!$B$75:$B$102,0)),"—") -> 25 | G32: =IFERROR(INDEX('드랍 구성 (개편)'!$Z$5:$Z$32,MATCH($A32,'드랍 구성 (개편)'!$B$5:$B$32,0)),"—") -> 20 | H32: =IFERROR(INDEX('드랍 구성 (개편)'!$Y$5:$Y$32,MATCH($A32,'드랍 구성 (개편)'!$B$5:$B$32,0)),"—") -> 금괴 | I32: =IFERROR(INDEX('드랍 구성 (개편)'!$Y$33:$Y$60,MATCH($A32,'드랍 구성 (개편)'!$B$33:$B$60,0)),"—") -> 사파이어 | J32: =IFERROR(INDEX('드랍 구성 (개편)'!$Y$61:$Y$74,MATCH($A32,'드랍 구성 (개편)'!$B$61:$B$74,0)),"—") -> 사파이어 | K32: =IFERROR(INDEX('드랍 구성 (개편)'!$Y$75:$Y$102,MATCH($A32,'드랍 구성 (개편)'!$B$75:$B$102,0)),"—") -> 사파이어 | L32: ='허들 설계'!R16 -> 루비
... A48: ='스테이지별 골드'!C32 -> 7-4 | B48: ='허들 설계'!F32 -> 대허들 | C48: =IFERROR(INDEX('드랍 구성 (개편)'!$V$5:$V$32,MATCH($A48,'드랍 구성 (개편)'!$B$5:$B$32,0)),"—") -> 26 | D48: =IFERROR(INDEX('드랍 구성 (개편)'!$V$33:$V$60,MATCH($A48,'드랍 구성 (개편)'!$B$33:$B$60,0)),"—") -> 31 | E48: =IFERROR(INDEX('드랍 구성 (개편)'!$V$61:$V$74,MATCH($A48,'드랍 구성 (개편)'!$B$61:$B$74,0)),"—") -> 37 | F48: =IFERROR(INDEX('드랍 구성 (개편)'!$V$75:$V$102,MATCH($A48,'드랍 구성 (개편)'!$B$75:$B$102,0)),"—") -> 44 | G48: =IFERROR(INDEX('드랍 구성 (개편)'!$Z$5:$Z$32,MATCH($A48,'드랍 구성 (개편)'!$B$5:$B$32,0)),"—") -> 6 | H48: =IFERROR(INDEX('드랍 구성 (개편)'!$Y$5:$Y$32,MATCH($A48,'드랍 구성 (개편)'!$B$5:$B$32,0)),"—") -> 루비 | I48: =IFERROR(INDEX('드랍 구성 (개편)'!$Y$33:$Y$60,MATCH($A48,'드랍 구성 (개편)'!$B$33:$B$60,0)),"—") -> 루비 | J48: =IFERROR(INDEX('드랍 구성 (개편)'!$Y$61:$Y$74,MATCH($A48,'드랍 구성 (개편)'!$B$61:$B$74,0)),"—") -> 다이아몬드 | K48: =IFERROR(INDEX('드랍 구성 (개편)'!$Y$75:$Y$102,MATCH($A48,'드랍 구성 (개편)'!$B$75:$B$102,0)),"—") -> 다이아몬드 | L48: ='허들 설계'!R32 -> 왕관

Sheet 설정
A1: 재화 배치 임시값 · 설정
A2: 파란 글씨 = 수정 가능한 입력값 / 노란 칸 = 핵심 가정 / 검정 = 수식 / 초록 = 다른 시트 참조. 입력값을 바꾸면 모든 시트가 다시 계산됩니다.
A4: 항목 | B4: 값 | C4: 단위 | D4: 설명
A5: 골드 계수 (체력 1당 골드) | B5: 0.1 | C5: 골드/체력 | D5: 건물 1개 골드 = 체력 × 골드 계수 × 유형 배율 (반올림). 체력에 비례해 시대가 갈수록 자연스럽게 증가
A6: 유형 배율: 일반 건물 | B6: 1 | C6: 배 | D6: 기준
A7: 유형 배율: 공격 건물 | B7: 1.2 | C7: 배 | D7: 드래곤을 공격하는 위험 보상. 체력이 일반의 약 1.3배라 실제 골드는 일반의 약 1.56배
A8: 유형 배율: 랜드마크 | B8: 1.5 | C8: 배 | D8: 짝수 스테이지 관문. 체력이 일반의 5배라 실제 골드는 일반의 7.5배
A9: 유형 배율: 황금 건물 | B9: 3 | C9: 배 | D9: 보너스 스테이지 잭팟. 체력이 일반의 1.5배라 실제 골드는 일반의 4.5배. 전부 부수면 보너스가 스테이지보다 많지만, 기력 제한으로 일부만 부수는 것을 전제
A10: 최소 드랍 개수 | B10: 5 | C10: 개 | D10: 건물 1개가 최소 이 개수 이상 쏟아지도록, 가능한 가장 높은 등급의 재화를 고름
A13: 인게임 드랍 자원
A14: 재화 | B14: 환산 골드 | C14: 첫 등장 (계산) | D14: 비고
A15: 금 코인 | B15: 1 | C15: =IFERROR(INDEX('드랍 구성'!$A$5:$A$102,MATCH(TRUE,INDEX('드랍 구성'!$J$5:$J$102>0,0),0))&" "&INDEX('드랍 구성'!$B$5:$B$102,MATCH(TRUE,INDEX('드랍 구성'!$J$5:$J$102>0,0),0)),"등장 안 함") -> 1-1 일반 | D15: 잔돈 처리용, 항상 드랍 가능
A16: 금괴 | B16: 5 | C16: =IFERROR(INDEX('드랍 구성'!$A$5:$A$102,MATCH(TRUE,INDEX('드랍 구성'!$I$5:$I$102>0,0),0))&" "&INDEX('드랍 구성'!$B$5:$B$102,MATCH(TRUE,INDEX('드랍 구성'!$I$5:$I$102>0,0),0)),"등장 안 함") -> 1-1 황금 (보너스)
A17: 사파이어 | B17: 25 | C17: =IFERROR(INDEX('드랍 구성'!$A$5:$A$102,MATCH(TRUE,INDEX('드랍 구성'!$H$5:$H$102>0,0),0))&" "&INDEX('드랍 구성'!$B$5:$B$102,MATCH(TRUE,INDEX('드랍 구성'!$H$5:$H$102>0,0),0)),"등장 안 함") -> 1-4 랜드마크
A18: 루비 | B18: 100 | C18: =IFERROR(INDEX('드랍 구성'!$A$5:$A$102,MATCH(TRUE,INDEX('드랍 구성'!$G$5:$G$102>0,0),0))&" "&INDEX('드랍 구성'!$B$5:$B$102,MATCH(TRUE,INDEX('드랍 구성'!$G$5:$G$102>0,0),0)),"등장 안 함") -> 3-4 랜드마크
A19: 다이아몬드 | B19: 500 | C19: =IFERROR(INDEX('드랍 구성'!$A$5:$A$102,MATCH(TRUE,INDEX('드랍 구성'!$F$5:$F$102>0,0),0))&" "&INDEX('드랍 구성'!$B$5:$B$102,MATCH(TRUE,INDEX('드랍 구성'!$F$5:$F$102>0,0),0)),"등장 안 함") -> 5-2 랜드마크
A20: 왕관 | B20: 1000 | C20: =IFERROR(INDEX('드랍 구성'!$A$5:$A$102,MATCH(TRUE,INDEX('드랍 구성'!$E$5:$E$102>0,0),0))&" "&INDEX('드랍 구성'!$B$5:$B$102,MATCH(TRUE,INDEX('드랍 구성'!$E$5:$E$102>0,0),0)),"등장 안 함") -> 6-2 랜드마크
A23: 개편안 (Ver03) · 건물 유형별 드랍 개수 곡선
A24: 목표 개수 = 기준 개수 × (1+스테이지당 증가율)^(순번-1) × (1+시대 돌파 증가율)^(시대-1). 개수는 스테이지마다 늘거나 유지되고, 새 시대에 들어서면 한 단계 더 늘어남.
A25: 건물 유형 | B25: 1-1 기준 개수 | C25: 스테이지당 증가율 | D25: 시대 돌파 증가율 | E25: 데뷔 지연 (스테이지) | F25: 설계 의도
A26: 일반 | B26: 10 | C26: 0.02 | D26: 0.07 | E26: 1 | F26: 기준선. 끝까지 2종 블렌드로 루비까지 도달, 다이아·왕관은 주지 않음
A27: 공격 | B27: 12 | C27: 0.02 | D27: 0.07 | E27: 1 | F27: 위험 보상. 일반보다 개수 20% 많고 상위 재화 비중이 반 시대 정도 앞섬
A28: 랜드마크 | B28: 20 | C28: 0.012 | D28: 0.05 | E28: 0 | F28: 관문·보스. 신규 재화가 처음 등장하는 무대 (데뷔 지연 0)
A29: 황금 (보너스) | B29: 18 | C29: 0.02 | D29: 0.06 | E29: 0 | F29: 잭팟. 가장 많이 쏟아지는 건물. 신규 재화를 보스 직후 보너스에서 바로 지급
A31: 재화 데뷔 일정 (대허들 돌파 보상)
A32: 각 재화는 데뷔 순번 + 데뷔 지연 이후 스테이지부터 드랍 가능 (1-1 기본 재화는 지연 없음). 홀수 시대 보스(x-4 랜드마크)에서 데뷔하고, 짝수 시대 보스에서 주력으로 승격되도록 맞춤.
A33: 재화 | B33: 데뷔 스테이지 | C33: 데뷔 순번 | D33: 비고
A34: =A15 -> 금 코인 | B34: 1-1 | C34: =(VALUE(LEFT(B34,1))-1)*4+VALUE(RIGHT(B34,1)) -> 1 | D34: 기본 재화
A35: =A16 -> 금괴 | B35: 1-1 | C35: =(VALUE(LEFT(B35,1))-1)*4+VALUE(RIGHT(B35,1)) -> 1 | D35: 기본 재화 (원시 시대는 코인→금괴 블렌드)
A36: =A17 -> 사파이어 | B36: 1-4 | C36: =(VALUE(LEFT(B36,1))-1)*4+VALUE(RIGHT(B36,1)) -> 4 | D36: 원시 보스 랜드마크에서 데뷔
A37: =A18 -> 루비 | B37: 3-4 | C37: =(VALUE(LEFT(B37,1))-1)*4+VALUE(RIGHT(B37,1)) -> 12 | D37: 중세 보스 랜드마크에서 데뷔
A38: =A19 -> 다이아몬드 | B38: 5-4 | C38: =(VALUE(LEFT(B38,1))-1)*4+VALUE(RIGHT(B38,1)) -> 20 | D38: 현대 보스 랜드마크에서 데뷔
A39: =A20 -> 왕관 | B39: 7-4 | C39: =(VALUE(LEFT(B39,1))-1)*4+VALUE(RIGHT(B39,1)) -> 28 | D39: 최종 보스(화성) 전용 엔딩 재화
A41: 허들 설계 기준
A42: 목표 반복 횟수 = 다음 스테이지로 가기 위해 직전 스테이지를 몇 번 플레이해야 하는지 (업그레이드 비용 설계 목표). 체력 배율은 레벨 디자인 원본 체력에 곱하는 제안값이며 골드 계산에는 쓰지 않음.
A43: 허들 등급 | B43: 목표 반복 횟수 | C43: 시대당 추가 반복 | D43: 체력 배율: 일반 | E43: 체력 배율: 공격 | F43: 체력 배율: 랜드마크 | G43: 설명
A44: 튜토리얼 | B44: 1 | C44: 0 | D44: 1 | E44: 1 | F44: 1 | G44: 1-1. 첫 업그레이드 없이 클리어
A45: 돌파 | B45: 1 | C45: 0 | D45: 0.9 | E45: 0.9 | F45: 0.9 | G45: x-1. 보스를 넘은 직후: 체력을 살짝 낮춰 "강해졌다"는 쾌감 + 새 시대 개수 증가
A46: 평탄 | B46: 1 | C46: 0 | D46: 1 | E46: 1 | F46: 1 | G46: x-3. 원본 곡선 그대로, 1회 클리어로 진행
A47: 소허들 | B47: 1.5 | C47: 0 | D47: 1 | E47: 1 | F47: 1.1 | G47: x-2. 지역 랜드마크 관문, 반 번 정도 추가 파밍
...

Sheet 스테이지별 골드
A1: 스테이지별 골드 배치 (임시값)
A2: 건물 수·체력은 레벨 디자인 Ver03 p07~p09 원본 값(파란 글씨). 골드는 설정 시트의 계수로 계산. 중세 지역 순서는 p07~p09 표 기준(독일 → 프랑스).
A3: 스테이지 | D3: 건물 수 (p07) | G3: 건물 체력 (p08) | J3: 건물별 골드 | N3: 보너스 스테이지 (p09) | R3: 합계
A4: 시대 | B4: 지역 | C4: 스테이지 | D4: 일반 | E4: 공격 | F4: 랜드마크 | G4: 일반 | H4: 공격 | I4: 랜드마크 | J4: 일반 1개 | K4: 공격 1개 | L4: 랜드마크 | M4: 스테이지 합계 | N4: 황금 건물 수 | O4: 황금 체력 | P4: 황금 1개 | Q4: 보너스 합계 | R4: 스테이지 + 보너스 | S4: 누적 골드
A5: 원시 | B5: 공룡 | C5: 1-1 | D5: 9 | E5: 1 | F5: 0 | G5: 100 | H5: 130 | I5: 0 | J5: =ROUND(G5*설정!$B$5*설정!$B$6,0) -> 10 | K5: =ROUND(H5*설정!$B$5*설정!$B$7,0) -> 16 | L5: =IF(F5=0,0,ROUND(I5*설정!$B$5*설정!$B$8,0)) -> 0 | M5: =D5*J5+E5*K5+F5*L5 -> 106 | N5: 10 | O5: 150 | P5: =ROUND(O5*설정!$B$5*설정!$B$9,0) -> 45 | Q5: =N5*P5 -> 450 | R5: =M5+Q5 -> 556 | S5: =SUM($R$5:R5) -> 556
A6: 원시 | B6: 공룡 | C6: 1-2 | D6: 10 | E6: 2 | F6: 1 | G6: 125 | H6: 165 | I6: 625 | J6: =ROUND(G6*설정!$B$5*설정!$B$6,0) -> 13 | K6: =ROUND(H6*설정!$B$5*설정!$B$7,0) -> 20 | L6: =IF(F6=0,0,ROUND(I6*설정!$B$5*설정!$B$8,0)) -> 94 | M6: =D6*J6+E6*K6+F6*L6 -> 264 | N6: 10 | O6: 188 | P6: =ROUND(O6*설정!$B$5*설정!$B$9,0) -> 56 | Q6: =N6*P6 -> 560 | R6: =M6+Q6 -> 824 | S6: =SUM($R$5:R6) -> 1380
A7: 원시 | B7: 원시인 | C7: 1-3 | D7: 11 | E7: 2 | F7: 0 | G7: 150 | H7: 200 | I7: 0 | J7: =ROUND(G7*설정!$B$5*설정!$B$6,0) -> 15 | K7: =ROUND(H7*설정!$B$5*설정!$B$7,0) -> 24 | L7: =IF(F7=0,0,ROUND(I7*설정!$B$5*설정!$B$8,0)) -> 0 | M7: =D7*J7+E7*K7+F7*L7 -> 213 | N7: 11 | O7: 225 | P7: =ROUND(O7*설정!$B$5*설정!$B$9,0) -> 68 | Q7: =N7*P7 -> 748 | R7: =M7+Q7 -> 961 | S7: =SUM($R$5:R7) -> 2341
A8: 원시 | B8: 원시인 | C8: 1-4 | D8: 12 | E8: 3 | F8: 1 | G8: 190 | H8: 250 | I8: 950 | J8: =ROUND(G8*설정!$B$5*설정!$B$6,0) -> 19 | K8: =ROUND(H8*설정!$B$5*설정!$B$7,0) -> 30 | L8: =IF(F8=0,0,ROUND(I8*설정!$B$5*설정!$B$8,0)) -> 143 | M8: =D8*J8+E8*K8+F8*L8 -> 461 | N8: 11 | O8: 285 | P8: =ROUND(O8*설정!$B$5*설정!$B$9,0) -> 86 | Q8: =N8*P8 -> 946 | R8: =M8+Q8 -> 1407 | S8: =SUM($R$5:R8) -> 3748
A9: 고대 | B9: 이집트 | C9: 2-1 | D9: 13 | E9: 3 | F9: 0 | G9: 230 | H9: 300 | I9: 0 | J9: =ROUND(G9*설정!$B$5*설정!$B$6,0) -> 23 | K9: =ROUND(H9*설정!$B$5*설정!$B$7,0) -> 36 | L9: =IF(F9=0,0,ROUND(I9*설정!$B$5*설정!$B$8,0)) -> 0 | M9: =D9*J9+E9*K9+F9*L9 -> 407 | N9: 12 | O9: 345 | P9: =ROUND(O9*설정!$B$5*설정!$B$9,0) -> 104 | Q9: =N9*P9 -> 1248 | R9: =M9+Q9 -> 1655 | S9: =SUM($R$5:R9) -> 5403
A10: 고대 | B10: 이집트 | C10: 2-2 | D10: 14 | E10: 4 | F10: 1 | G10: 290 | H10: 380 | I10: 1450 | J10: =ROUND(G10*설정!$B$5*설정!$B$6,0) -> 29 | K10: =ROUND(H10*설정!$B$5*설정!$B$7,0) -> 46 | L10: =IF(F10=0,0,ROUND(I10*설정!$B$5*설정!$B$8,0)) -> 218 | M10: =D10*J10+E10*K10+F10*L10 -> 808 | N10: 12 | O10: 435 | P10: =ROUND(O10*설정!$B$5*설정!$B$9,0) -> 131 | Q10: =N10*P10 -> 1572 | R10: =M10+Q10 -> 2380 | S10: =SUM($R$5:R10) -> 7783
A11: 고대 | B11: 그리스 | C11: 2-3 | D11: 15 | E11: 4 | F11: 0 | G11: 350 | H11: 460 | I11: 0 | J11: =ROUND(G11*설정!$B$5*설정!$B$6,0) -> 35 | K11: =ROUND(H11*설정!$B$5*설정!$B$7,0) -> 55 | L11: =IF(F11=0,0,ROUND(I11*설정!$B$5*설정!$B$8,0)) -> 0 | M11: =D11*J11+E11*K11+F11*L11 -> 745 | N11: 13 | O11: 525 | P11: =ROUND(O11*설정!$B$5*설정!$B$9,0) -> 158 | Q11: =N11*P11 -> 2054 | R11: =M11+Q11 -> 2799 | S11: =SUM($R$5:R11) -> 10582
A12: 고대 | B12: 그리스 | C12: 2-4 | D12: 16 | E12: 5 | F12: 1 | G12: 440 | H12: 575 | I12: 2200 | J12: =ROUND(G12*설정!$B$5*설정!$B$6,0) -> 44 | K12: =ROUND(H12*설정!$B$5*설정!$B$7,0) -> 69 | L12: =IF(F12=0,0,ROUND(I12*설정!$B$5*설정!$B$8,0)) -> 330 | M12: =D12*J12+E12*K12+F12*L12 -> 1379 | N12: 13 | O12: 660 | P12: =ROUND(O12*설정!$B$5*설정!$B$9,0) -> 198 | Q12: =N12*P12 -> 2574 | R12: =M12+Q12 -> 3953 | S12: =SUM($R$5:R12) -> 14535
A13: 중세 | B13: 프랑스 | C13: 3-1 | D13: 17 | E13: 5 | F13: 0 | G13: 530 | H13: 700 | I13: 0 | J13: =ROUND(G13*설정!$B$5*설정!$B$6,0) -> 53 | K13: =ROUND(H13*설정!$B$5*설정!$B$7,0) -> 84 | L13: =IF(F13=0,0,ROUND(I13*설정!$B$5*설정!$B$8,0)) -> 0 | M13: =D13*J13+E13*K13+F13*L13 -> 1321 | N13: 14 | O13: 795 | P13: =ROUND(O13*설정!$B$5*설정!$B$9,0) -> 239 | Q13: =N13*P13 -> 3346 | R13: =M13+Q13 -> 4667 | S13: =SUM($R$5:R13) -> 19202
A14: 중세 | B14: 프랑스 | C14: 3-2 | D14: 18 | E14: 6 | F14: 1 | G14: 660 | H14: 860 | I14: 3300 | J14: =ROUND(G14*설정!$B$5*설정!$B$6,0) -> 66 | K14: =ROUND(H14*설정!$B$5*설정!$B$7,0) -> 103 | L14: =IF(F14=0,0,ROUND(I14*설정!$B$5*설정!$B$8,0)) -> 495 | M14: =D14*J14+E14*K14+F14*L14 -> 2301 | N14: 14 | O14: 990 | P14: =ROUND(O14*설정!$B$5*설정!$B$9,0) -> 297 | Q14: =N14*P14 -> 4158 | R14: =M14+Q14 -> 6459 | S14: =SUM($R$5:R14) -> 25661
A15: 중세 | B15: 독일 | C15: 3-3 | D15: 19 | E15: 6 | F15: 0 | G15: 800 | H15: 1050 | I15: 0 | J15: =ROUND(G15*설정!$B$5*설정!$B$6,0) -> 80 | K15: =ROUND(H15*설정!$B$5*설정!$B$7,0) -> 126 | L15: =IF(F15=0,0,ROUND(I15*설정!$B$5*설정!$B$8,0)) -> 0 | M15: =D15*J15+E15*K15+F15*L15 -> 2276 | N15: 15 | O15: 1200 | P15: =ROUND(O15*설정!$B$5*설정!$B$9,0) -> 360 | Q15: =N15*P15 -> 5400 | R15: =M15+Q15 -> 7676 | S15: =SUM($R$5:R15) -> 33337
A16: 중세 | B16: 독일 | C16: 3-4 | D16: 20 | E16: 7 | F16: 1 | G16: 1000 | H16: 1300 | I16: 5000 | J16: =ROUND(G16*설정!$B$5*설정!$B$6,0) -> 100 | K16: =ROUND(H16*설정!$B$5*설정!$B$7,0) -> 156 | L16: =IF(F16=0,0,ROUND(I16*설정!$B$5*설정!$B$8,0)) -> 750 | M16: =D16*J16+E16*K16+F16*L16 -> 3842 | N16: 15 | O16: 1500 | P16: =ROUND(O16*설정!$B$5*설정!$B$9,0) -> 450 | Q16: =N16*P16 -> 6750 | R16: =M16+Q16 -> 10592 | S16: =SUM($R$5:R16) -> 43929
... A32: 우주 | B32: 화성 | C32: 7-4 | D32: 36 | E32: 15 | F32: 1 | G32: 26000 | H32: 33800 | I32: 130000 | J32: =ROUND(G32*설정!$B$5*설정!$B$6,0) -> 2600 | K32: =ROUND(H32*설정!$B$5*설정!$B$7,0) -> 4056 | L32: =IF(F32=0,0,ROUND(I32*설정!$B$5*설정!$B$8,0)) -> 19500 | M32: =D32*J32+E32*K32+F32*L32 -> 173940 | N32: 23 | O32: 39000 | P32: =ROUND(O32*설정!$B$5*설정!$B$9,0) -> 11700 | Q32: =N32*P32 -> 269100 | R32: =M32+Q32 -> 443040 | S32: =SUM($R$5:R32) -> 2107893
A33: 합계 | D33: =SUM(D5:D32) -> 630 | E33: =SUM(E5:E32) -> 224 | F33: =SUM(F5:F32) -> 14 | M33: =SUM(M5:M32) -> 778681 | N33: =SUM(N5:N32) -> 462 | Q33: =SUM(Q5:Q32) -> 1329212 | R33: =SUM(R5:R32) -> 2107893

Sheet 허들 설계
A1: 스테이지 허들 설계 · 개편안 (Ver03)
A2: 시대(4스테이지) 단위 리듬: 돌파(x-1) → 소허들(x-2) → 평탄(x-3) → 대허들(x-4 보스). 허들 등급(파란 글씨)을 바꾸면 반복 횟수·제안 체력·요구 골드가 다시 계산됨.
A4: 시대 | B4: 지역 | C4: 스테이지 | D4: 순번 | E4: 시대 번호 | F4: 허들 등급 | G4: 목표 반복 횟수 | H4: 일반 체력 (원본) | I4: 일반 체력 (제안) | J4: 공격 체력 (원본) | K4: 공격 체력 (제안) | L4: 랜드마크 체력 (원본) | M4: 랜드마크 체력 (제안) | N4: 일반 체력 증가율 (제안) | O4: 1회 기대 골드 (개편) | P4: 업그레이드 요구 골드 (가이드) | Q4: 누적 플레이 횟수 | R4: 신규 재화 데뷔 | S4: 설계 의도
A5: ='스테이지별 골드'!A5 -> 원시 | B5: ='스테이지별 골드'!B5 -> 공룡 | C5: ='스테이지별 골드'!C5 -> 1-1 | D5: =ROW()-4 -> 1 | E5: =INT((D5-1)/4)+1 -> 1 | F5: 튜토리얼 | G5: =INDEX(설정!$B$44:$B$48,MATCH(F5,설정!$A$44:$A$48,0))+INDEX(설정!$C$44:$C$48,MATCH(F5,설정!$A$44:$A$48,0))*(E5-1) -> 1 | H5: ='스테이지별 골드'!G5 -> 100 | I5: =ROUND(H5*INDEX(설정!$D$44:$D$48,MATCH(F5,설정!$A$44:$A$48,0)),0) -> 100 | J5: ='스테이지별 골드'!H5 -> 130 | K5: =ROUND(J5*INDEX(설정!$E$44:$E$48,MATCH(F5,설정!$A$44:$A$48,0)),0) -> 130 | L5: ='스테이지별 골드'!I5 -> 0 | M5: =ROUND(L5*INDEX(설정!$F$44:$F$48,MATCH(F5,설정!$A$44:$A$48,0)),0) -> 0 | N5: - | O5: =SUMIFS('드랍 구성 (개편)'!$AB$5:$AB$102,'드랍 구성 (개편)'!$B$5:$B$102,C5,'드랍 구성 (개편)'!$A$5:$A$102,"<>황금 (보너스)")+설정!$B$50*SUMIFS('드랍 구성 (개편)'!$AB$5:$AB$102,'드랍 구성 (개편)'!$B$5:$B$102,C5,'드랍 구성 (개편)'!$A$5:$A$102,"황금 (보너스)") -> 244 | P5: 0 | Q5: =SUM($G$5:G5) -> 1 | R5: 금 코인 · 금괴 (기본) | S5: 코인만 쏟아지는 첫 경험. 업그레이드 없이 클리어
A6: ='스테이지별 골드'!A6 -> 원시 | B6: ='스테이지별 골드'!B6 -> 공룡 | C6: ='스테이지별 골드'!C6 -> 1-2 | D6: =ROW()-4 -> 2 | E6: =INT((D6-1)/4)+1 -> 1 | F6: 소허들 | G6: =INDEX(설정!$B$44:$B$48,MATCH(F6,설정!$A$44:$A$48,0))+INDEX(설정!$C$44:$C$48,MATCH(F6,설정!$A$44:$A$48,0))*(E6-1) -> 1.5 | H6: ='스테이지별 골드'!G6 -> 125 | I6: =ROUND(H6*INDEX(설정!$D$44:$D$48,MATCH(F6,설정!$A$44:$A$48,0)),0) -> 125 | J6: ='스테이지별 골드'!H6 -> 165 | K6: =ROUND(J6*INDEX(설정!$E$44:$E$48,MATCH(F6,설정!$A$44:$A$48,0)),0) -> 165 | L6: ='스테이지별 골드'!I6 -> 625 | M6: =ROUND(L6*INDEX(설정!$F$44:$F$48,MATCH(F6,설정!$A$44:$A$48,0)),0) -> 688 | N6: =I6/I5-1 -> 0.25 | O6: =SUMIFS('드랍 구성 (개편)'!$AB$5:$AB$102,'드랍 구성 (개편)'!$B$5:$B$102,C6,'드랍 구성 (개편)'!$A$5:$A$102,"<>황금 (보너스)")+설정!$B$50*SUMIFS('드랍 구성 (개편)'!$AB$5:$AB$102,'드랍 구성 (개편)'!$B$5:$B$102,C6,'드랍 구성 (개편)'!$A$5:$A$102,"황금 (보너스)") -> 450 | P6: =ROUND(G6*O5,0) -> 366 | Q6: =SUM($G$5:G6) -> 2.5 | R6: =IFERROR(INDEX(설정!$A$34:$A$39,MATCH(D6,설정!$C$34:$C$39,0)),"") | S6: 지역 랜드마크 관문. 직전 스테이지를 0.5회 정도 추가 파밍
A7: ='스테이지별 골드'!A7 -> 원시 | B7: ='스테이지별 골드'!B7 -> 원시인 | C7: ='스테이지별 골드'!C7 -> 1-3 | D7: =ROW()-4 -> 3 | E7: =INT((D7-1)/4)+1 -> 1 | F7: 평탄 | G7: =INDEX(설정!$B$44:$B$48,MATCH(F7,설정!$A$44:$A$48,0))+INDEX(설정!$C$44:$C$48,MATCH(F7,설정!$A$44:$A$48,0))*(E7-1) -> 1 | H7: ='스테이지별 골드'!G7 -> 150 | I7: =ROUND(H7*INDEX(설정!$D$44:$D$48,MATCH(F7,설정!$A$44:$A$48,0)),0) -> 150 | J7: ='스테이지별 골드'!H7 -> 200 | K7: =ROUND(J7*INDEX(설정!$E$44:$E$48,MATCH(F7,설정!$A$44:$A$48,0)),0) -> 200 | L7: ='스테이지별 골드'!I7 -> 0 | M7: =ROUND(L7*INDEX(설정!$F$44:$F$48,MATCH(F7,설정!$A$44:$A$48,0)),0) -> 0 | N7: =I7/I6-1 -> 0.2 | O7: =SUMIFS('드랍 구성 (개편)'!$AB$5:$AB$102,'드랍 구성 (개편)'!$B$5:$B$102,C7,'드랍 구성 (개편)'!$A$5:$A$102,"<>황금 (보너스)")+설정!$B$50*SUMIFS('드랍 구성 (개편)'!$AB$5:$AB$102,'드랍 구성 (개편)'!$B$5:$B$102,C7,'드랍 구성 (개편)'!$A$5:$A$102,"황금 (보너스)") -> 423.1 | P7: =ROUND(G7*O6,0) -> 450 | Q7: =SUM($G$5:G7) -> 3.5 | R7: =IFERROR(INDEX(설정!$A$34:$A$39,MATCH(D7,설정!$C$34:$C$39,0)),"") | S7: 원본 곡선. 다음 재화 비중이 조금씩 오름
A8: ='스테이지별 골드'!A8 -> 원시 | B8: ='스테이지별 골드'!B8 -> 원시인 | C8: ='스테이지별 골드'!C8 -> 1-4 | D8: =ROW()-4 -> 4 | E8: =INT((D8-1)/4)+1 -> 1 | F8: 대허들 | G8: =INDEX(설정!$B$44:$B$48,MATCH(F8,설정!$A$44:$A$48,0))+INDEX(설정!$C$44:$C$48,MATCH(F8,설정!$A$44:$A$48,0))*(E8-1) -> 2 | H8: ='스테이지별 골드'!G8 -> 190 | I8: =ROUND(H8*INDEX(설정!$D$44:$D$48,MATCH(F8,설정!$A$44:$A$48,0)),0) -> 190 | J8: ='스테이지별 골드'!H8 -> 250 | K8: =ROUND(J8*INDEX(설정!$E$44:$E$48,MATCH(F8,설정!$A$44:$A$48,0)),0) -> 325 | L8: ='스테이지별 골드'!I8 -> 950 | M8: =ROUND(L8*INDEX(설정!$F$44:$F$48,MATCH(F8,설정!$A$44:$A$48,0)),0) -> 1235 | N8: =I8/I7-1 -> 0.26666667 | O8: =SUMIFS('드랍 구성 (개편)'!$AB$5:$AB$102,'드랍 구성 (개편)'!$B$5:$B$102,C8,'드랍 구성 (개편)'!$A$5:$A$102,"<>황금 (보너스)")+설정!$B$50*SUMIFS('드랍 구성 (개편)'!$AB$5:$AB$102,'드랍 구성 (개편)'!$B$5:$B$102,C8,'드랍 구성 (개편)'!$A$5:$A$102,"황금 (보너스)") -> 747.1 | P8: =ROUND(G8*O7,0) -> 846 | Q8: =SUM($G$5:G8) -> 5.5 | R8: =IFERROR(INDEX(설정!$A$34:$A$39,MATCH(D8,설정!$C$34:$C$39,0)),"") -> 사파이어 | S8: 시대 보스. 공격·랜드마크 체력 상향, 반복 파밍이 필요한 벽
A9: ='스테이지별 골드'!A9 -> 고대 | B9: ='스테이지별 골드'!B9 -> 이집트 | C9: ='스테이지별 골드'!C9 -> 2-1 | D9: =ROW()-4 -> 5 | E9: =INT((D9-1)/4)+1 -> 2 | F9: 돌파 | G9: =INDEX(설정!$B$44:$B$48,MATCH(F9,설정!$A$44:$A$48,0))+INDEX(설정!$C$44:$C$48,MATCH(F9,설정!$A$44:$A$48,0))*(E9-1) -> 1 | H9: ='스테이지별 골드'!G9 -> 230 | I9: =ROUND(H9*INDEX(설정!$D$44:$D$48,MATCH(F9,설정!$A$44:$A$48,0)),0) -> 207 | J9: ='스테이지별 골드'!H9 -> 300 | K9: =ROUND(J9*INDEX(설정!$E$44:$E$48,MATCH(F9,설정!$A$44:$A$48,0)),0) -> 270 | L9: ='스테이지별 골드'!I9 -> 0 | M9: =ROUND(L9*INDEX(설정!$F$44:$F$48,MATCH(F9,설정!$A$44:$A$48,0)),0) -> 0 | N9: =I9/I8-1 -> 0.089473684 | O9: =SUMIFS('드랍 구성 (개편)'!$AB$5:$AB$102,'드랍 구성 (개편)'!$B$5:$B$102,C9,'드랍 구성 (개편)'!$A$5:$A$102,"<>황금 (보너스)")+설정!$B$50*SUMIFS('드랍 구성 (개편)'!$AB$5:$AB$102,'드랍 구성 (개편)'!$B$5:$B$102,C9,'드랍 구성 (개편)'!$A$5:$A$102,"황금 (보너스)") -> 804 | P9: =ROUND(G9*O8,0) -> 747 | Q9: =SUM($G$5:G9) -> 6.5 | R9: =IFERROR(INDEX(설정!$A$34:$A$39,MATCH(D9,설정!$C$34:$C$39,0)),"") | S9: 보스 직후 체력 -10%, 새 시대 개수 +7%: 성장을 체감시키는 구간
A10: ='스테이지별 골드'!A10 -> 고대 | B10: ='스테이지별 골드'!B10 -> 이집트 | C10: ='스테이지별 골드'!C10 -> 2-2 | D10: =ROW()-4 -> 6 | E10: =INT((D10-1)/4)+1 -> 2 | F10: 소허들 | G10: =INDEX(설정!$B$44:$B$48,MATCH(F10,설정!$A$44:$A$48,0))+INDEX(설정!$C$44:$C$48,MATCH(F10,설정!$A$44:$A$48,0))*(E10-1) -> 1.5 | H10: ='스테이지별 골드'!G10 -> 290 | I10: =ROUND(H10*INDEX(설정!$D$44:$D$48,MATCH(F10,설정!$A$44:$A$48,0)),0) -> 290 | J10: ='스테이지별 골드'!H10 -> 380 | K10: =ROUND(J10*INDEX(설정!$E$44:$E$48,MATCH(F10,설정!$A$44:$A$48,0)),0) -> 380 | L10: ='스테이지별 골드'!I10 -> 1450 | M10: =ROUND(L10*INDEX(설정!$F$44:$F$48,MATCH(F10,설정!$A$44:$A$48,0)),0) -> 1595 | N10: =I10/I9-1 -> 0.40096618 | O10: =SUMIFS('드랍 구성 (개편)'!$AB$5:$AB$102,'드랍 구성 (개편)'!$B$5:$B$102,C10,'드랍 구성 (개편)'!$A$5:$A$102,"<>황금 (보너스)")+설정!$B$50*SUMIFS('드랍 구성 (개편)'!$AB$5:$AB$102,'드랍 구성 (개편)'!$B$5:$B$102,C10,'드랍 구성 (개편)'!$A$5:$A$102,"황금 (보너스)") -> 1236 | P10: =ROUND(G10*O9,0) -> 1206 | Q10: =SUM($G$5:G10) -> 8 | R10: =IFERROR(INDEX(설정!$A$34:$A$39,MATCH(D10,설정!$C$34:$C$39,0)),"") | S10: 지역 랜드마크 관문. 직전 스테이지를 0.5회 정도 추가 파밍
A11: ='스테이지별 골드'!A11 -> 고대 | B11: ='스테이지별 골드'!B11 -> 그리스 | C11: ='스테이지별 골드'!C11 -> 2-3 | D11: =ROW()-4 -> 7 | E11: =INT((D11-1)/4)+1 -> 2 | F11: 평탄 | G11: =INDEX(설정!$B$44:$B$48,MATCH(F11,설정!$A$44:$A$48,0))+INDEX(설정!$C$44:$C$48,MATCH(F11,설정!$A$44:$A$48,0))*(E11-1) -> 1 | H11: ='스테이지별 골드'!G11 -> 350 | I11: =ROUND(H11*INDEX(설정!$D$44:$D$48,MATCH(F11,설정!$A$44:$A$48,0)),0) -> 350 | J11: ='스테이지별 골드'!H11 -> 460 | K11: =ROUND(J11*INDEX(설정!$E$44:$E$48,MATCH(F11,설정!$A$44:$A$48,0)),0) -> 460 | L11: ='스테이지별 골드'!I11 -> 0 | M11: =ROUND(L11*INDEX(설정!$F$44:$F$48,MATCH(F11,설정!$A$44:$A$48,0)),0) -> 0 | N11: =I11/I10-1 -> 0.20689655 | O11: =SUMIFS('드랍 구성 (개편)'!$AB$5:$AB$102,'드랍 구성 (개편)'!$B$5:$B$102,C11,'드랍 구성 (개편)'!$A$5:$A$102,"<>황금 (보너스)")+설정!$B$50*SUMIFS('드랍 구성 (개편)'!$AB$5:$AB$102,'드랍 구성 (개편)'!$B$5:$B$102,C11,'드랍 구성 (개편)'!$A$5:$A$102,"황금 (보너스)") -> 1399.5 | P11: =ROUND(G11*O10,0) -> 1236 | Q11: =SUM($G$5:G11) -> 9 | R11: =IFERROR(INDEX(설정!$A$34:$A$39,MATCH(D11,설정!$C$34:$C$39,0)),"") | S11: 원본 곡선. 다음 재화 비중이 조금씩 오름
A12: ='스테이지별 골드'!A12 -> 고대 | B12: ='스테이지별 골드'!B12 -> 그리스 | C12: ='스테이지별 골드'!C12 -> 2-4 | D12: =ROW()-4 -> 8 | E12: =INT((D12-1)/4)+1 -> 2 | F12: 대허들 | G12: =INDEX(설정!$B$44:$B$48,MATCH(F12,설정!$A$44:$A$48,0))+INDEX(설정!$C$44:$C$48,MATCH(F12,설정!$A$44:$A$48,0))*(E12-1) -> 2.5 | H12: ='스테이지별 골드'!G12 -> 440 | I12: =ROUND(H12*INDEX(설정!$D$44:$D$48,MATCH(F12,설정!$A$44:$A$48,0)),0) -> 440 | J12: ='스테이지별 골드'!H12 -> 575 | K12: =ROUND(J12*INDEX(설정!$E$44:$E$48,MATCH(F12,설정!$A$44:$A$48,0)),0) -> 748 | L12: ='스테이지별 골드'!I12 -> 2200 | M12: =ROUND(L12*INDEX(설정!$F$44:$F$48,MATCH(F12,설정!$A$44:$A$48,0)),0) -> 2860 | N12: =I12/I11-1 -> 0.25714286 | O12: =SUMIFS('드랍 구성 (개편)'!$AB$5:$AB$102,'드랍 구성 (개편)'!$B$5:$B$102,C12,'드랍 구성 (개편)'!$A$5:$A$102,"<>황금 (보너스)")+설정!$B$50*SUMIFS('드랍 구성 (개편)'!$AB$5:$AB$102,'드랍 구성 (개편)'!$B$5:$B$102,C12,'드랍 구성 (개편)'!$A$5:$A$102,"황금 (보너스)") -> 2135 | P12: =ROUND(G12*O11,0) -> 3499 | Q12: =SUM($G$5:G12) -> 11.5 | R12: =IFERROR(INDEX(설정!$A$34:$A$39,MATCH(D12,설정!$C$34:$C$39,0)),"") | S12: 시대 보스. 공격·랜드마크 체력 상향, 반복 파밍이 필요한 벽
A13: ='스테이지별 골드'!A13 -> 중세 | B13: ='스테이지별 골드'!B13 -> 프랑스 | C13: ='스테이지별 골드'!C13 -> 3-1 | D13: =ROW()-4 -> 9 | E13: =INT((D13-1)/4)+1 -> 3 | F13: 돌파 | G13: =INDEX(설정!$B$44:$B$48,MATCH(F13,설정!$A$44:$A$48,0))+INDEX(설정!$C$44:$C$48,MATCH(F13,설정!$A$44:$A$48,0))*(E13-1) -> 1 | H13: ='스테이지별 골드'!G13 -> 530 | I13: =ROUND(H13*INDEX(설정!$D$44:$D$48,MATCH(F13,설정!$A$44:$A$48,0)),0) -> 477 | J13: ='스테이지별 골드'!H13 -> 700 | K13: =ROUND(J13*INDEX(설정!$E$44:$E$48,MATCH(F13,설정!$A$44:$A$48,0)),0) -> 630 | L13: ='스테이지별 골드'!I13 -> 0 | M13: =ROUND(L13*INDEX(설정!$F$44:$F$48,MATCH(F13,설정!$A$44:$A$48,0)),0) -> 0 | N13: =I13/I12-1 -> 0.084090909 | O13: =SUMIFS('드랍 구성 (개편)'!$AB$5:$AB$102,'드랍 구성 (개편)'!$B$5:$B$102,C13,'드랍 구성 (개편)'!$A$5:$A$102,"<>황금 (보너스)")+설정!$B$50*SUMIFS('드랍 구성 (개편)'!$AB$5:$AB$102,'드랍 구성 (개편)'!$B$5:$B$102,C13,'드랍 구성 (개편)'!$A$5:$A$102,"황금 (보너스)") -> 2309 | P13: =ROUND(G13*O12,0) -> 2135 | Q13: =SUM($G$5:G13) -> 12.5 | R13: =IFERROR(INDEX(설정!$A$34:$A$39,MATCH(D13,설정!$C$34:$C$39,0)),"") | S13: 보스 직후 체력 -10%, 새 시대 개수 +7%: 성장을 체감시키는 구간
A14: ='스테이지별 골드'!A14 -> 중세 | B14: ='스테이지별 골드'!B14 -> 프랑스 | C14: ='스테이지별 골드'!C14 -> 3-2 | D14: =ROW()-4 -> 10 | E14: =INT((D14-1)/4)+1 -> 3 | F14: 소허들 | G14: =INDEX(설정!$B$44:$B$48,MATCH(F14,설정!$A$44:$A$48,0))+INDEX(설정!$C$44:$C$48,MATCH(F14,설정!$A$44:$A$48,0))*(E14-1) -> 1.5 | H14: ='스테이지별 골드'!G14 -> 660 | I14: =ROUND(H14*INDEX(설정!$D$44:$D$48,MATCH(F14,설정!$A$44:$A$48,0)),0) -> 660 | J14: ='스테이지별 골드'!H14 -> 860 | K14: =ROUND(J14*INDEX(설정!$E$44:$E$48,MATCH(F14,설정!$A$44:$A$48,0)),0) -> 860 | L14: ='스테이지별 골드'!I14 -> 3300 | M14: =ROUND(L14*INDEX(설정!$F$44:$F$48,MATCH(F14,설정!$A$44:$A$48,0)),0) -> 3630 | N14: =I14/I13-1 -> 0.3836478 | O14: =SUMIFS('드랍 구성 (개편)'!$AB$5:$AB$102,'드랍 구성 (개편)'!$B$5:$B$102,C14,'드랍 구성 (개편)'!$A$5:$A$102,"<>황금 (보너스)")+설정!$B$50*SUMIFS('드랍 구성 (개편)'!$AB$5:$AB$102,'드랍 구성 (개편)'!$B$5:$B$102,C14,'드랍 구성 (개편)'!$A$5:$A$102,"황금 (보너스)") -> 3553 | P14: =ROUND(G14*O13,0) -> 3464 | Q14: =SUM($G$5:G14) -> 14 | R14: =IFERROR(INDEX(설정!$A$34:$A$39,MATCH(D14,설정!$C$34:$C$39,0)),"") | S14: 지역 랜드마크 관문. 직전 스테이지를 0.5회 정도 추가 파밍
A15: ='스테이지별 골드'!A15 -> 중세 | B15: ='스테이지별 골드'!B15 -> 독일 | C15: ='스테이지별 골드'!C15 -> 3-3 | D15: =ROW()-4 -> 11 | E15: =INT((D15-1)/4)+1 -> 3 | F15: 평탄 | G15: =INDEX(설정!$B$44:$B$48,MATCH(F15,설정!$A$44:$A$48,0))+INDEX(설정!$C$44:$C$48,MATCH(F15,설정!$A$44:$A$48,0))*(E15-1) -> 1 | H15: ='스테이지별 골드'!G15 -> 800 | I15: =ROUND(H15*INDEX(설정!$D$44:$D$48,MATCH(F15,설정!$A$44:$A$48,0)),0) -> 800 | J15: ='스테이지별 골드'!H15 -> 1050 | K15: =ROUND(J15*INDEX(설정!$E$44:$E$48,MATCH(F15,설정!$A$44:$A$48,0)),0) -> 1050 | L15: ='스테이지별 골드'!I15 -> 0 | M15: =ROUND(L15*INDEX(설정!$F$44:$F$48,MATCH(F15,설정!$A$44:$A$48,0)),0) -> 0 | N15: =I15/I14-1 -> 0.21212121 | O15: =SUMIFS('드랍 구성 (개편)'!$AB$5:$AB$102,'드랍 구성 (개편)'!$B$5:$B$102,C15,'드랍 구성 (개편)'!$A$5:$A$102,"<>황금 (보너스)")+설정!$B$50*SUMIFS('드랍 구성 (개편)'!$AB$5:$AB$102,'드랍 구성 (개편)'!$B$5:$B$102,C15,'드랍 구성 (개편)'!$A$5:$A$102,"황금 (보너스)") -> 4102.5 | P15: =ROUND(G15*O14,0) -> 3553 | Q15: =SUM($G$5:G15) -> 15 | R15: =IFERROR(INDEX(설정!$A$34:$A$39,MATCH(D15,설정!$C$34:$C$39,0)),"") | S15: 원본 곡선. 다음 재화 비중이 조금씩 오름
A16: ='스테이지별 골드'!A16 -> 중세 | B16: ='스테이지별 골드'!B16 -> 독일 | C16: ='스테이지별 골드'!C16 -> 3-4 | D16: =ROW()-4 -> 12 | E16: =INT((D16-1)/4)+1 -> 3 | F16: 대허들 | G16: =INDEX(설정!$B$44:$B$48,MATCH(F16,설정!$A$44:$A$48,0))+INDEX(설정!$C$44:$C$48,MATCH(F16,설정!$A$44:$A$48,0))*(E16-1) -> 3 | H16: ='스테이지별 골드'!G16 -> 1000 | I16: =ROUND(H16*INDEX(설정!$D$44:$D$48,MATCH(F16,설정!$A$44:$A$48,0)),0) -> 1000 | J16: ='스테이지별 골드'!H16 -> 1300 | K16: =ROUND(J16*INDEX(설정!$E$44:$E$48,MATCH(F16,설정!$A$44:$A$48,0)),0) -> 1690 | L16: ='스테이지별 골드'!I16 -> 5000 | M16: =ROUND(L16*INDEX(설정!$F$44:$F$48,MATCH(F16,설정!$A$44:$A$48,0)),0) -> 6500 | N16: =I16/I15-1 -> 0.25 | O16: =SUMIFS('드랍 구성 (개편)'!$AB$5:$AB$102,'드랍 구성 (개편)'!$B$5:$B$102,C16,'드랍 구성 (개편)'!$A$5:$A$102,"<>황금 (보너스)")+설정!$B$50*SUMIFS('드랍 구성 (개편)'!$AB$5:$AB$102,'드랍 구성 (개편)'!$B$5:$B$102,C16,'드랍 구성 (개편)'!$A$5:$A$102,"황금 (보너스)") -> 6132.5 | P16: =ROUND(G16*O15,0) -> 12308 | Q16: =SUM($G$5:G16) -> 18 | R16: =IFERROR(INDEX(설정!$A$34:$A$39,MATCH(D16,설정!$C$34:$C$39,0)),"") -> 루비 | S16: 시대 보스. 공격·랜드마크 체력 상향, 반복 파밍이 필요한 벽
A17: ='스테이지별 골드'!A17 -> 산업 | B17: ='스테이지별 골드'!B17 -> 영국 | C17: ='스테이지별 골드'!C17 -> 4-1 | D17: =ROW()-4 -> 13 | E17: =INT((D17-1)/4)+1 -> 4 | F17: 돌파 | G17: =INDEX(설정!$B$44:$B$48,MATCH(F17,설정!$A$44:$A$48,0))+INDEX(설정!$C$44:$C$48,MATCH(F17,설정!$A$44:$A$48,0))*(E17-1) -> 1 | H17: ='스테이지별 골드'!G17 -> 1200 | I17: =ROUND(H17*INDEX(설정!$D$44:$D$48,MATCH(F17,설정!$A$44:$A$48,0)),0) -> 1080 | J17: ='스테이지별 골드'!H17 -> 1560 | K17: =ROUND(J17*INDEX(설정!$E$44:$E$48,MATCH(F17,설정!$A$44:$A$48,0)),0) -> 1404 | L17: ='스테이지별 골드'!I17 -> 0 | M17: =ROUND(L17*INDEX(설정!$F$44:$F$48,MATCH(F17,설정!$A$44:$A$48,0)),0) -> 0 | N17: =I17/I16-1 -> 0.08 | O17: =SUMIFS('드랍 구성 (개편)'!$AB$5:$AB$102,'드랍 구성 (개편)'!$B$5:$B$102,C17,'드랍 구성 (개편)'!$A$5:$A$102,"<>황금 (보너스)")+설정!$B$50*SUMIFS('드랍 구성 (개편)'!$AB$5:$AB$102,'드랍 구성 (개편)'!$B$5:$B$102,C17,'드랍 구성 (개편)'!$A$5:$A$102,"황금 (보너스)") -> 6453 | P17: =ROUND(G17*O16,0) -> 6133 | Q17: =SUM($G$5:G17) -> 19 | R17: =IFERROR(INDEX(설정!$A$34:$A$39,MATCH(D17,설정!$C$34:$C$39,0)),"") | S17: 보스 직후 체력 -10%, 새 시대 개수 +7%: 성장을 체감시키는 구간
... A32: ='스테이지별 골드'!A32 -> 우주 | B32: ='스테이지별 골드'!B32 -> 화성 | C32: ='스테이지별 골드'!C32 -> 7-4 | D32: =ROW()-4 -> 28 | E32: =INT((D32-1)/4)+1 -> 7 | F32: 대허들 | G32: =INDEX(설정!$B$44:$B$48,MATCH(F32,설정!$A$44:$A$48,0))+INDEX(설정!$C$44:$C$48,MATCH(F32,설정!$A$44:$A$48,0))*(E32-1) -> 5 | H32: ='스테이지별 골드'!G32 -> 26000 | I32: =ROUND(H32*INDEX(설정!$D$44:$D$48,MATCH(F32,설정!$A$44:$A$48,0)),0) -> 26000 | J32: ='스테이지별 골드'!H32 -> 33800 | K32: =ROUND(J32*INDEX(설정!$E$44:$E$48,MATCH(F32,설정!$A$44:$A$48,0)),0) -> 43940 | L32: ='스테이지별 골드'!I32 -> 130000 | M32: =ROUND(L32*INDEX(설정!$F$44:$F$48,MATCH(F32,설정!$A$44:$A$48,0)),0) -> 169000 | N32: =I32/I31-1 -> 0.23809524 | O32: =SUMIFS('드랍 구성 (개편)'!$AB$5:$AB$102,'드랍 구성 (개편)'!$B$5:$B$102,C32,'드랍 구성 (개편)'!$A$5:$A$102,"<>황금 (보너스)")+설정!$B$50*SUMIFS('드랍 구성 (개편)'!$AB$5:$AB$102,'드랍 구성 (개편)'!$B$5:$B$102,C32,'드랍 구성 (개편)'!$A$5:$A$102,"황금 (보너스)") -> 251640 | P32: =ROUND(G32*O31,0) -> 937625 | Q32: =SUM($G$5:G32) -> 49 | R32: =IFERROR(INDEX(설정!$A$34:$A$39,MATCH(D32,설정!$C$34:$C$39,0)),"") -> 왕관 | S32: 시대 보스. 공격·랜드마크 체력 상향, 반복 파밍이 필요한 벽
A33: 합계 | G33: =SUM(G5:G32) -> 49 | O33: =SUM(O5:O32) -> 1177445.2 | P33: =SUM(P5:P32) -> 2144071

Sheet 드랍 구성
A1: 건물 1개당 드랍 구성 (임시값)
A2: 골드를 「최소 드랍 개수」 이상이 되는 가장 높은 등급부터 채우고, 남는 금액은 낮은 등급으로 채움. 개수 = 화면에 쏟아지는 재화 오브젝트 수.
D3: 환산 골드 → | E3: =설정!$B$20 -> 1000 | F3: =설정!$B$19 -> 500 | G3: =설정!$B$18 -> 100 | H3: =설정!$B$17 -> 25 | I3: =설정!$B$16 -> 5 | J3: =설정!$B$15 -> 1
A4: 스테이지 | B4: 건물 유형 | C4: 골드 / 개 | D4: 최고 등급 (골드) | E4: 왕관 | F4: 다이아몬드 | G4: 루비 | H4: 사파이어 | I4: 금괴 | J4: 금 코인 | K4: 드랍 개수 | L4: 검산 (골드)
A5: ='스테이지별 골드'!C5 -> 1-1 | B5: 일반 | C5: ='스테이지별 골드'!J5 -> 10 | D5: =IF(C5>=E$3*설정!$B$10,E$3,IF(C5>=F$3*설정!$B$10,F$3,IF(C5>=G$3*설정!$B$10,G$3,IF(C5>=H$3*설정!$B$10,H$3,IF(C5>=I$3*설정!$B$10,I$3,J$3))))) -> 1 | E5: =IF(E$3<=$D5,INT($C5/E$3),0) -> 0 | F5: =IF(F$3<=$D5,INT(($C5-SUMPRODUCT($E5:E5,$E$3:E$3))/F$3),0) -> 0 | G5: =IF(G$3<=$D5,INT(($C5-SUMPRODUCT($E5:F5,$E$3:F$3))/G$3),0) -> 0 | H5: =IF(H$3<=$D5,INT(($C5-SUMPRODUCT($E5:G5,$E$3:G$3))/H$3),0) -> 0 | I5: =IF(I$3<=$D5,INT(($C5-SUMPRODUCT($E5:H5,$E$3:H$3))/I$3),0) -> 0 | J5: =INT(($C5-SUMPRODUCT($E5:I5,$E$3:I$3))/J$3) -> 10 | K5: =SUM(E5:J5) -> 10 | L5: =SUMPRODUCT(E5:J5,$E$3:$J$3) -> 10
A6: ='스테이지별 골드'!C5 -> 1-1 | B6: 공격 | C6: ='스테이지별 골드'!K5 -> 16 | D6: =IF(C6>=E$3*설정!$B$10,E$3,IF(C6>=F$3*설정!$B$10,F$3,IF(C6>=G$3*설정!$B$10,G$3,IF(C6>=H$3*설정!$B$10,H$3,IF(C6>=I$3*설정!$B$10,I$3,J$3))))) -> 1 | E6: =IF(E$3<=$D6,INT($C6/E$3),0) -> 0 | F6: =IF(F$3<=$D6,INT(($C6-SUMPRODUCT($E6:E6,$E$3:E$3))/F$3),0) -> 0 | G6: =IF(G$3<=$D6,INT(($C6-SUMPRODUCT($E6:F6,$E$3:F$3))/G$3),0) -> 0 | H6: =IF(H$3<=$D6,INT(($C6-SUMPRODUCT($E6:G6,$E$3:G$3))/H$3),0) -> 0 | I6: =IF(I$3<=$D6,INT(($C6-SUMPRODUCT($E6:H6,$E$3:H$3))/I$3),0) -> 0 | J6: =INT(($C6-SUMPRODUCT($E6:I6,$E$3:I$3))/J$3) -> 16 | K6: =SUM(E6:J6) -> 16 | L6: =SUMPRODUCT(E6:J6,$E$3:$J$3) -> 16
A7: ='스테이지별 골드'!C5 -> 1-1 | B7: 황금 (보너스) | C7: ='스테이지별 골드'!P5 -> 45 | D7: =IF(C7>=E$3*설정!$B$10,E$3,IF(C7>=F$3*설정!$B$10,F$3,IF(C7>=G$3*설정!$B$10,G$3,IF(C7>=H$3*설정!$B$10,H$3,IF(C7>=I$3*설정!$B$10,I$3,J$3))))) -> 5 | E7: =IF(E$3<=$D7,INT($C7/E$3),0) -> 0 | F7: =IF(F$3<=$D7,INT(($C7-SUMPRODUCT($E7:E7,$E$3:E$3))/F$3),0) -> 0 | G7: =IF(G$3<=$D7,INT(($C7-SUMPRODUCT($E7:F7,$E$3:F$3))/G$3),0) -> 0 | H7: =IF(H$3<=$D7,INT(($C7-SUMPRODUCT($E7:G7,$E$3:G$3))/H$3),0) -> 0 | I7: =IF(I$3<=$D7,INT(($C7-SUMPRODUCT($E7:H7,$E$3:H$3))/I$3),0) -> 9 | J7: =INT(($C7-SUMPRODUCT($E7:I7,$E$3:I$3))/J$3) -> 0 | K7: =SUM(E7:J7) -> 9 | L7: =SUMPRODUCT(E7:J7,$E$3:$J$3) -> 45
A8: ='스테이지별 골드'!C6 -> 1-2 | B8: 일반 | C8: ='스테이지별 골드'!J6 -> 13 | D8: =IF(C8>=E$3*설정!$B$10,E$3,IF(C8>=F$3*설정!$B$10,F$3,IF(C8>=G$3*설정!$B$10,G$3,IF(C8>=H$3*설정!$B$10,H$3,IF(C8>=I$3*설정!$B$10,I$3,J$3))))) -> 1 | E8: =IF(E$3<=$D8,INT($C8/E$3),0) -> 0 | F8: =IF(F$3<=$D8,INT(($C8-SUMPRODUCT($E8:E8,$E$3:E$3))/F$3),0) -> 0 | G8: =IF(G$3<=$D8,INT(($C8-SUMPRODUCT($E8:F8,$E$3:F$3))/G$3),0) -> 0 | H8: =IF(H$3<=$D8,INT(($C8-SUMPRODUCT($E8:G8,$E$3:G$3))/H$3),0) -> 0 | I8: =IF(I$3<=$D8,INT(($C8-SUMPRODUCT($E8:H8,$E$3:H$3))/I$3),0) -> 0 | J8: =INT(($C8-SUMPRODUCT($E8:I8,$E$3:I$3))/J$3) -> 13 | K8: =SUM(E8:J8) -> 13 | L8: =SUMPRODUCT(E8:J8,$E$3:$J$3) -> 13
A9: ='스테이지별 골드'!C6 -> 1-2 | B9: 공격 | C9: ='스테이지별 골드'!K6 -> 20 | D9: =IF(C9>=E$3*설정!$B$10,E$3,IF(C9>=F$3*설정!$B$10,F$3,IF(C9>=G$3*설정!$B$10,G$3,IF(C9>=H$3*설정!$B$10,H$3,IF(C9>=I$3*설정!$B$10,I$3,J$3))))) -> 1 | E9: =IF(E$3<=$D9,INT($C9/E$3),0) -> 0 | F9: =IF(F$3<=$D9,INT(($C9-SUMPRODUCT($E9:E9,$E$3:E$3))/F$3),0) -> 0 | G9: =IF(G$3<=$D9,INT(($C9-SUMPRODUCT($E9:F9,$E$3:F$3))/G$3),0) -> 0 | H9: =IF(H$3<=$D9,INT(($C9-SUMPRODUCT($E9:G9,$E$3:G$3))/H$3),0) -> 0 | I9: =IF(I$3<=$D9,INT(($C9-SUMPRODUCT($E9:H9,$E$3:H$3))/I$3),0) -> 0 | J9: =INT(($C9-SUMPRODUCT($E9:I9,$E$3:I$3))/J$3) -> 20 | K9: =SUM(E9:J9) -> 20 | L9: =SUMPRODUCT(E9:J9,$E$3:$J$3) -> 20
A10: ='스테이지별 골드'!C6 -> 1-2 | B10: 랜드마크 | C10: ='스테이지별 골드'!L6 -> 94 | D10: =IF(C10>=E$3*설정!$B$10,E$3,IF(C10>=F$3*설정!$B$10,F$3,IF(C10>=G$3*설정!$B$10,G$3,IF(C10>=H$3*설정!$B$10,H$3,IF(C10>=I$3*설정!$B$10,I$3,J$3))))) -> 5 | E10: =IF(E$3<=$D10,INT($C10/E$3),0) -> 0 | F10: =IF(F$3<=$D10,INT(($C10-SUMPRODUCT($E10:E10,$E$3:E$3))/F$3),0) -> 0 | G10: =IF(G$3<=$D10,INT(($C10-SUMPRODUCT($E10:F10,$E$3:F$3))/G$3),0) -> 0 | H10: =IF(H$3<=$D10,INT(($C10-SUMPRODUCT($E10:G10,$E$3:G$3))/H$3),0) -> 0 | I10: =IF(I$3<=$D10,INT(($C10-SUMPRODUCT($E10:H10,$E$3:H$3))/I$3),0) -> 18 | J10: =INT(($C10-SUMPRODUCT($E10:I10,$E$3:I$3))/J$3) -> 4 | K10: =SUM(E10:J10) -> 22 | L10: =SUMPRODUCT(E10:J10,$E$3:$J$3) -> 94
A11: ='스테이지별 골드'!C6 -> 1-2 | B11: 황금 (보너스) | C11: ='스테이지별 골드'!P6 -> 56 | D11: =IF(C11>=E$3*설정!$B$10,E$3,IF(C11>=F$3*설정!$B$10,F$3,IF(C11>=G$3*설정!$B$10,G$3,IF(C11>=H$3*설정!$B$10,H$3,IF(C11>=I$3*설정!$B$10,I$3,J$3))))) -> 5 | E11: =IF(E$3<=$D11,INT($C11/E$3),0) -> 0 | F11: =IF(F$3<=$D11,INT(($C11-SUMPRODUCT($E11:E11,$E$3:E$3))/F$3),0) -> 0 | G11: =IF(G$3<=$D11,INT(($C11-SUMPRODUCT($E11:F11,$E$3:F$3))/G$3),0) -> 0 | H11: =IF(H$3<=$D11,INT(($C11-SUMPRODUCT($E11:G11,$E$3:G$3))/H$3),0) -> 0 | I11: =IF(I$3<=$D11,INT(($C11-SUMPRODUCT($E11:H11,$E$3:H$3))/I$3),0) -> 11 | J11: =INT(($C11-SUMPRODUCT($E11:I11,$E$3:I$3))/J$3) -> 1 | K11: =SUM(E11:J11) -> 12 | L11: =SUMPRODUCT(E11:J11,$E$3:$J$3) -> 56
A12: ='스테이지별 골드'!C7 -> 1-3 | B12: 일반 | C12: ='스테이지별 골드'!J7 -> 15 | D12: =IF(C12>=E$3*설정!$B$10,E$3,IF(C12>=F$3*설정!$B$10,F$3,IF(C12>=G$3*설정!$B$10,G$3,IF(C12>=H$3*설정!$B$10,H$3,IF(C12>=I$3*설정!$B$10,I$3,J$3))))) -> 1 | E12: =IF(E$3<=$D12,INT($C12/E$3),0) -> 0 | F12: =IF(F$3<=$D12,INT(($C12-SUMPRODUCT($E12:E12,$E$3:E$3))/F$3),0) -> 0 | G12: =IF(G$3<=$D12,INT(($C12-SUMPRODUCT($E12:F12,$E$3:F$3))/G$3),0) -> 0 | H12: =IF(H$3<=$D12,INT(($C12-SUMPRODUCT($E12:G12,$E$3:G$3))/H$3),0) -> 0 | I12: =IF(I$3<=$D12,INT(($C12-SUMPRODUCT($E12:H12,$E$3:H$3))/I$3),0) -> 0 | J12: =INT(($C12-SUMPRODUCT($E12:I12,$E$3:I$3))/J$3) -> 15 | K12: =SUM(E12:J12) -> 15 | L12: =SUMPRODUCT(E12:J12,$E$3:$J$3) -> 15
A13: ='스테이지별 골드'!C7 -> 1-3 | B13: 공격 | C13: ='스테이지별 골드'!K7 -> 24 | D13: =IF(C13>=E$3*설정!$B$10,E$3,IF(C13>=F$3*설정!$B$10,F$3,IF(C13>=G$3*설정!$B$10,G$3,IF(C13>=H$3*설정!$B$10,H$3,IF(C13>=I$3*설정!$B$10,I$3,J$3))))) -> 1 | E13: =IF(E$3<=$D13,INT($C13/E$3),0) -> 0 | F13: =IF(F$3<=$D13,INT(($C13-SUMPRODUCT($E13:E13,$E$3:E$3))/F$3),0) -> 0 | G13: =IF(G$3<=$D13,INT(($C13-SUMPRODUCT($E13:F13,$E$3:F$3))/G$3),0) -> 0 | H13: =IF(H$3<=$D13,INT(($C13-SUMPRODUCT($E13:G13,$E$3:G$3))/H$3),0) -> 0 | I13: =IF(I$3<=$D13,INT(($C13-SUMPRODUCT($E13:H13,$E$3:H$3))/I$3),0) -> 0 | J13: =INT(($C13-SUMPRODUCT($E13:I13,$E$3:I$3))/J$3) -> 24 | K13: =SUM(E13:J13) -> 24 | L13: =SUMPRODUCT(E13:J13,$E$3:$J$3) -> 24
A14: ='스테이지별 골드'!C7 -> 1-3 | B14: 황금 (보너스) | C14: ='스테이지별 골드'!P7 -> 68 | D14: =IF(C14>=E$3*설정!$B$10,E$3,IF(C14>=F$3*설정!$B$10,F$3,IF(C14>=G$3*설정!$B$10,G$3,IF(C14>=H$3*설정!$B$10,H$3,IF(C14>=I$3*설정!$B$10,I$3,J$3))))) -> 5 | E14: =IF(E$3<=$D14,INT($C14/E$3),0) -> 0 | F14: =IF(F$3<=$D14,INT(($C14-SUMPRODUCT($E14:E14,$E$3:E$3))/F$3),0) -> 0 | G14: =IF(G$3<=$D14,INT(($C14-SUMPRODUCT($E14:F14,$E$3:F$3))/G$3),0) -> 0 | H14: =IF(H$3<=$D14,INT(($C14-SUMPRODUCT($E14:G14,$E$3:G$3))/H$3),0) -> 0 | I14: =IF(I$3<=$D14,INT(($C14-SUMPRODUCT($E14:H14,$E$3:H$3))/I$3),0) -> 13 | J14: =INT(($C14-SUMPRODUCT($E14:I14,$E$3:I$3))/J$3) -> 3 | K14: =SUM(E14:J14) -> 16 | L14: =SUMPRODUCT(E14:J14,$E$3:$J$3) -> 68
A15: ='스테이지별 골드'!C8 -> 1-4 | B15: 일반 | C15: ='스테이지별 골드'!J8 -> 19 | D15: =IF(C15>=E$3*설정!$B$10,E$3,IF(C15>=F$3*설정!$B$10,F$3,IF(C15>=G$3*설정!$B$10,G$3,IF(C15>=H$3*설정!$B$10,H$3,IF(C15>=I$3*설정!$B$10,I$3,J$3))))) -> 1 | E15: =IF(E$3<=$D15,INT($C15/E$3),0) -> 0 | F15: =IF(F$3<=$D15,INT(($C15-SUMPRODUCT($E15:E15,$E$3:E$3))/F$3),0) -> 0 | G15: =IF(G$3<=$D15,INT(($C15-SUMPRODUCT($E15:F15,$E$3:F$3))/G$3),0) -> 0 | H15: =IF(H$3<=$D15,INT(($C15-SUMPRODUCT($E15:G15,$E$3:G$3))/H$3),0) -> 0 | I15: =IF(I$3<=$D15,INT(($C15-SUMPRODUCT($E15:H15,$E$3:H$3))/I$3),0) -> 0 | J15: =INT(($C15-SUMPRODUCT($E15:I15,$E$3:I$3))/J$3) -> 19 | K15: =SUM(E15:J15) -> 19 | L15: =SUMPRODUCT(E15:J15,$E$3:$J$3) -> 19
A16: ='스테이지별 골드'!C8 -> 1-4 | B16: 공격 | C16: ='스테이지별 골드'!K8 -> 30 | D16: =IF(C16>=E$3*설정!$B$10,E$3,IF(C16>=F$3*설정!$B$10,F$3,IF(C16>=G$3*설정!$B$10,G$3,IF(C16>=H$3*설정!$B$10,H$3,IF(C16>=I$3*설정!$B$10,I$3,J$3))))) -> 5 | E16: =IF(E$3<=$D16,INT($C16/E$3),0) -> 0 | F16: =IF(F$3<=$D16,INT(($C16-SUMPRODUCT($E16:E16,$E$3:E$3))/F$3),0) -> 0 | G16: =IF(G$3<=$D16,INT(($C16-SUMPRODUCT($E16:F16,$E$3:F$3))/G$3),0) -> 0 | H16: =IF(H$3<=$D16,INT(($C16-SUMPRODUCT($E16:G16,$E$3:G$3))/H$3),0) -> 0 | I16: =IF(I$3<=$D16,INT(($C16-SUMPRODUCT($E16:H16,$E$3:H$3))/I$3),0) -> 6 | J16: =INT(($C16-SUMPRODUCT($E16:I16,$E$3:I$3))/J$3) -> 0 | K16: =SUM(E16:J16) -> 6 | L16: =SUMPRODUCT(E16:J16,$E$3:$J$3) -> 30
A17: ='스테이지별 골드'!C8 -> 1-4 | B17: 랜드마크 | C17: ='스테이지별 골드'!L8 -> 143 | D17: =IF(C17>=E$3*설정!$B$10,E$3,IF(C17>=F$3*설정!$B$10,F$3,IF(C17>=G$3*설정!$B$10,G$3,IF(C17>=H$3*설정!$B$10,H$3,IF(C17>=I$3*설정!$B$10,I$3,J$3))))) -> 25 | E17: =IF(E$3<=$D17,INT($C17/E$3),0) -> 0 | F17: =IF(F$3<=$D17,INT(($C17-SUMPRODUCT($E17:E17,$E$3:E$3))/F$3),0) -> 0 | G17: =IF(G$3<=$D17,INT(($C17-SUMPRODUCT($E17:F17,$E$3:F$3))/G$3),0) -> 0 | H17: =IF(H$3<=$D17,INT(($C17-SUMPRODUCT($E17:G17,$E$3:G$3))/H$3),0) -> 5 | I17: =IF(I$3<=$D17,INT(($C17-SUMPRODUCT($E17:H17,$E$3:H$3))/I$3),0) -> 3 | J17: =INT(($C17-SUMPRODUCT($E17:I17,$E$3:I$3))/J$3) -> 3 | K17: =SUM(E17:J17) -> 11 | L17: =SUMPRODUCT(E17:J17,$E$3:$J$3) -> 143
A18: ='스테이지별 골드'!C8 -> 1-4 | B18: 황금 (보너스) | C18: ='스테이지별 골드'!P8 -> 86 | D18: =IF(C18>=E$3*설정!$B$10,E$3,IF(C18>=F$3*설정!$B$10,F$3,IF(C18>=G$3*설정!$B$10,G$3,IF(C18>=H$3*설정!$B$10,H$3,IF(C18>=I$3*설정!$B$10,I$3,J$3))))) -> 5 | E18: =IF(E$3<=$D18,INT($C18/E$3),0) -> 0 | F18: =IF(F$3<=$D18,INT(($C18-SUMPRODUCT($E18:E18,$E$3:E$3))/F$3),0) -> 0 | G18: =IF(G$3<=$D18,INT(($C18-SUMPRODUCT($E18:F18,$E$3:F$3))/G$3),0) -> 0 | H18: =IF(H$3<=$D18,INT(($C18-SUMPRODUCT($E18:G18,$E$3:G$3))/H$3),0) -> 0 | I18: =IF(I$3<=$D18,INT(($C18-SUMPRODUCT($E18:H18,$E$3:H$3))/I$3),0) -> 17 | J18: =INT(($C18-SUMPRODUCT($E18:I18,$E$3:I$3))/J$3) -> 1 | K18: =SUM(E18:J18) -> 18 | L18: =SUMPRODUCT(E18:J18,$E$3:$J$3) -> 86
A19: ='스테이지별 골드'!C9 -> 2-1 | B19: 일반 | C19: ='스테이지별 골드'!J9 -> 23 | D19: =IF(C19>=E$3*설정!$B$10,E$3,IF(C19>=F$3*설정!$B$10,F$3,IF(C19>=G$3*설정!$B$10,G$3,IF(C19>=H$3*설정!$B$10,H$3,IF(C19>=I$3*설정!$B$10,I$3,J$3))))) -> 1 | E19: =IF(E$3<=$D19,INT($C19/E$3),0) -> 0 | F19: =IF(F$3<=$D19,INT(($C19-SUMPRODUCT($E19:E19,$E$3:E$3))/F$3),0) -> 0 | G19: =IF(G$3<=$D19,INT(($C19-SUMPRODUCT($E19:F19,$E$3:F$3))/G$3),0) -> 0 | H19: =IF(H$3<=$D19,INT(($C19-SUMPRODUCT($E19:G19,$E$3:G$3))/H$3),0) -> 0 | I19: =IF(I$3<=$D19,INT(($C19-SUMPRODUCT($E19:H19,$E$3:H$3))/I$3),0) -> 0 | J19: =INT(($C19-SUMPRODUCT($E19:I19,$E$3:I$3))/J$3) -> 23 | K19: =SUM(E19:J19) -> 23 | L19: =SUMPRODUCT(E19:J19,$E$3:$J$3) -> 23
A20: ='스테이지별 골드'!C9 -> 2-1 | B20: 공격 | C20: ='스테이지별 골드'!K9 -> 36 | D20: =IF(C20>=E$3*설정!$B$10,E$3,IF(C20>=F$3*설정!$B$10,F$3,IF(C20>=G$3*설정!$B$10,G$3,IF(C20>=H$3*설정!$B$10,H$3,IF(C20>=I$3*설정!$B$10,I$3,J$3))))) -> 5 | E20: =IF(E$3<=$D20,INT($C20/E$3),0) -> 0 | F20: =IF(F$3<=$D20,INT(($C20-SUMPRODUCT($E20:E20,$E$3:E$3))/F$3),0) -> 0 | G20: =IF(G$3<=$D20,INT(($C20-SUMPRODUCT($E20:F20,$E$3:F$3))/G$3),0) -> 0 | H20: =IF(H$3<=$D20,INT(($C20-SUMPRODUCT($E20:G20,$E$3:G$3))/H$3),0) -> 0 | I20: =IF(I$3<=$D20,INT(($C20-SUMPRODUCT($E20:H20,$E$3:H$3))/I$3),0) -> 7 | J20: =INT(($C20-SUMPRODUCT($E20:I20,$E$3:I$3))/J$3) -> 1 | K20: =SUM(E20:J20) -> 8 | L20: =SUMPRODUCT(E20:J20,$E$3:$J$3) -> 36
A21: ='스테이지별 골드'!C9 -> 2-1 | B21: 황금 (보너스) | C21: ='스테이지별 골드'!P9 -> 104 | D21: =IF(C21>=E$3*설정!$B$10,E$3,IF(C21>=F$3*설정!$B$10,F$3,IF(C21>=G$3*설정!$B$10,G$3,IF(C21>=H$3*설정!$B$10,H$3,IF(C21>=I$3*설정!$B$10,I$3,J$3))))) -> 5 | E21: =IF(E$3<=$D21,INT($C21/E$3),0) -> 0 | F21: =IF(F$3<=$D21,INT(($C21-SUMPRODUCT($E21:E21,$E$3:E$3))/F$3),0) -> 0 | G21: =IF(G$3<=$D21,INT(($C21-SUMPRODUCT($E21:F21,$E$3:F$3))/G$3),0) -> 0 | H21: =IF(H$3<=$D21,INT(($C21-SUMPRODUCT($E21:G21,$E$3:G$3))/H$3),0) -> 0 | I21: =IF(I$3<=$D21,INT(($C21-SUMPRODUCT($E21:H21,$E$3:H$3))/I$3),0) -> 20 | J21: =INT(($C21-SUMPRODUCT($E21:I21,$E$3:I$3))/J$3) -> 4 | K21: =SUM(E21:J21) -> 24 | L21: =SUMPRODUCT(E21:J21,$E$3:$J$3) -> 104
A22: ='스테이지별 골드'!C10 -> 2-2 | B22: 일반 | C22: ='스테이지별 골드'!J10 -> 29 | D22: =IF(C22>=E$3*설정!$B$10,E$3,IF(C22>=F$3*설정!$B$10,F$3,IF(C22>=G$3*설정!$B$10,G$3,IF(C22>=H$3*설정!$B$10,H$3,IF(C22>=I$3*설정!$B$10,I$3,J$3))))) -> 5 | E22: =IF(E$3<=$D22,INT($C22/E$3),0) -> 0 | F22: =IF(F$3<=$D22,INT(($C22-SUMPRODUCT($E22:E22,$E$3:E$3))/F$3),0) -> 0 | G22: =IF(G$3<=$D22,INT(($C22-SUMPRODUCT($E22:F22,$E$3:F$3))/G$3),0) -> 0 | H22: =IF(H$3<=$D22,INT(($C22-SUMPRODUCT($E22:G22,$E$3:G$3))/H$3),0) -> 0 | I22: =IF(I$3<=$D22,INT(($C22-SUMPRODUCT($E22:H22,$E$3:H$3))/I$3),0) -> 5 | J22: =INT(($C22-SUMPRODUCT($E22:I22,$E$3:I$3))/J$3) -> 4 | K22: =SUM(E22:J22) -> 9 | L22: =SUMPRODUCT(E22:J22,$E$3:$J$3) -> 29
A23: ='스테이지별 골드'!C10 -> 2-2 | B23: 공격 | C23: ='스테이지별 골드'!K10 -> 46 | D23: =IF(C23>=E$3*설정!$B$10,E$3,IF(C23>=F$3*설정!$B$10,F$3,IF(C23>=G$3*설정!$B$10,G$3,IF(C23>=H$3*설정!$B$10,H$3,IF(C23>=I$3*설정!$B$10,I$3,J$3))))) -> 5 | E23: =IF(E$3<=$D23,INT($C23/E$3),0) -> 0 | F23: =IF(F$3<=$D23,INT(($C23-SUMPRODUCT($E23:E23,$E$3:E$3))/F$3),0) -> 0 | G23: =IF(G$3<=$D23,INT(($C23-SUMPRODUCT($E23:F23,$E$3:F$3))/G$3),0) -> 0 | H23: =IF(H$3<=$D23,INT(($C23-SUMPRODUCT($E23:G23,$E$3:G$3))/H$3),0) -> 0 | I23: =IF(I$3<=$D23,INT(($C23-SUMPRODUCT($E23:H23,$E$3:H$3))/I$3),0) -> 9 | J23: =INT(($C23-SUMPRODUCT($E23:I23,$E$3:I$3))/J$3) -> 1 | K23: =SUM(E23:J23) -> 10 | L23: =SUMPRODUCT(E23:J23,$E$3:$J$3) -> 46
A24: ='스테이지별 골드'!C10 -> 2-2 | B24: 랜드마크 | C24: ='스테이지별 골드'!L10 -> 218 | D24: =IF(C24>=E$3*설정!$B$10,E$3,IF(C24>=F$3*설정!$B$10,F$3,IF(C24>=G$3*설정!$B$10,G$3,IF(C24>=H$3*설정!$B$10,H$3,IF(C24>=I$3*설정!$B$10,I$3,J$3))))) -> 25 | E24: =IF(E$3<=$D24,INT($C24/E$3),0) -> 0 | F24: =IF(F$3<=$D24,INT(($C24-SUMPRODUCT($E24:E24,$E$3:E$3))/F$3),0) -> 0 | G24: =IF(G$3<=$D24,INT(($C24-SUMPRODUCT($E24:F24,$E$3:F$3))/G$3),0) -> 0 | H24: =IF(H$3<=$D24,INT(($C24-SUMPRODUCT($E24:G24,$E$3:G$3))/H$3),0) -> 8 | I24: =IF(I$3<=$D24,INT(($C24-SUMPRODUCT($E24:H24,$E$3:H$3))/I$3),0) -> 3 | J24: =INT(($C24-SUMPRODUCT($E24:I24,$E$3:I$3))/J$3) -> 3 | K24: =SUM(E24:J24) -> 14 | L24: =SUMPRODUCT(E24:J24,$E$3:$J$3) -> 218
